Workbook

Sheet Premissas
A1: PREMISSAS — Break-Even Logística São Mateus/ES
A2: Campos em AZUL = você preenche | Preto = calculado automaticamente
A3: 1. RECEITA POR PACOTE
A4: Item | B4: Valor | C4: Observação
A5: Receita por pacote entregue (R$) | B5: 4.5 | C5: Valor pago pela franqueadora
A6: Receita por tentativa sem sucesso (R$) | B6: 0 | C6: Geralmente R$ 0 — confirme
A8: 2. CUSTOS VARIÁVEIS (por pacote tentado)
A9: Item | B9: Valor | C9: Observação
A10: Comissão motoboy / entregador | B10: 2 | C10: Por tentativa de entrega
A11: Combustível (frota própria) | B11: 0.4 | C11: Estimativa por pacote
A12: Embalagem / lacre | B12: 0.1 | C12: Se necessário
A13: Outros variáveis | B13: 0
A14: TOTAL VARIÁVEL POR PACOTE | B14: =SUM(B10:B13)
A16: 3. CUSTOS FIXOS MENSAIS
A17: Item | B17: Valor | C17: Observação
A18: Aluguel do galpão | B18: 3000 | C18: 150-200m² em São Mateus
A19: Taxa de franquia / royalties | B19: 800 | C19: Varia por franqueadora
A20: Salário funcionário 1 (triagem) | B20: 2000 | C20: CLT ou PJ
A21: Salário funcionário 2 (apoio) | B21: 0 | C21: Se necessário
A22: Energia elétrica | B22: 300
A23: Internet + sistema de rastreio | B23: 200
A24: Seguro | B24: 150
A25: Contabilidade | B25: 200
A26: Reserva para imprevistos | B26: 350
A27: Outros fixos | B27: 0
A28: TOTAL FIXO MENSAL | B28: =SUM(B18:B27)
A30: 4. PARÂMETROS OPERACIONAIS
A31: Parâmetro | B31: Valor | C31: Observação
A32: Taxa de insucesso de entrega | B32: 0.15 | C32: 0.15 = 15% tentativas sem sucesso
A33: Dias úteis por mês | B33: 24 | C33: Para break-even diário
A34: Volume alvo estabilizado (pac/mês) | B34: 3000 | C34: Meta em regime normal
A36: 5. RAMP-UP — % do volume alvo por mês
A37: Período | B37: % Volume Alvo | C37: Observação
A38: Mês 1 | B38: 0.3
A39: Mês 2 | B39: 0.45
A40: Mês 3 | B40: 0.6
A41: Mês 4 | B41: 0.75
A42: Mês 5 | B42: 0.85
A43: Mês 6 | B43: 0.95
A44: Meses 7 a 12 | B44: 1 | C44: Volume estabilizado
...

Sheet Break-Even
A1: BREAK-EVEN — Cálculo e Análise de Sensibilidade
A2: Alimentado pelas Premissas — não edite esta aba
A3: COMPONENTES
A4: Item | B4: Valor
A5: Receita por pacote entregue | B5: =Premissas!B5
A6: Custo variável por pacote | B6: =Premissas!B14
A7: MARGEM DE CONTRIBUIÇÃO por pacote | B7: =B5-B6
A9: Custo fixo mensal | B9: =Premissas!B28
A10: Taxa de insucesso | B10: =Premissas!B32
A11: Dias úteis por mês | B11: =Premissas!B33
A13: BREAK-EVEN
A14: Métrica | B14: Valor
A15: Break-even simples (pac/mês) | B15: =IFERROR(B9/B7,"MC=0")
A16: Break-even simples (pac/dia útil) | B16: =IFERROR(B15/B11,"--")
A17: Break-even AJUSTADO (pac recebidos/mês) | B17: =IFERROR(B15/(1-B10),"--")
A18: Break-even ajustado (pac recebidos/dia útil) | B18: =IFERROR(B17/B11,"--")
A20: CAPITAL NECESSÁRIO ANTES DE ABRIR
A21: Item | B21: Valor
A22: Investimento inicial | B22: =Premissas!B48
A23: Reserva de custo fixo em caixa | B23: =Premissas!B49*Premissas!B28
A24: Déficit acumulado ramp-up (da aba Projecao) | B24: =Projecao!I19
A25: CAPITAL TOTAL NECESSÁRIO | B25: =B22+B23+B24
A28: SENSIBILIDADE — Break-Even em pac/mês | Linhas = Custo Fixo Mensal | Colunas = Margem de Contribuição por pacote
A29: Fixo \ MC | B29: R$ 1.00 | C29: R$ 1.50 | D29: R$ 2.00 | E29: R$ 2.50 | F29: R$ 3.00 | G29: R$ 3.50 | H29: R$ 4.00
A30: R$ 4.000 | B30: =ROUND(4000/1.0000,0) | C30: =ROUND(4000/1.5000,0) | D30: =ROUND(4000/2.0000,0) | E30: =ROUND(4000/2.5000,0) | F30: =ROUND(4000/3.0000,0) | G30: =ROUND(4000/3.5000,0) | H30: =ROUND(4000/4.0000,0)
A31: R$ 5.000 | B31: =ROUND(5000/1.0000,0) | C31: =ROUND(5000/1.5000,0) | D31: =ROUND(5000/2.0000,0) | E31: =ROUND(5000/2.5000,0) | F31: =ROUND(5000/3.0000,0) | G31: =ROUND(5000/3.5000,0) | H31: =ROUND(5000/4.0000,0)
A32: R$ 6.000 | B32: =ROUND(6000/1.0000,0) | C32: =ROUND(6000/1.5000,0) | D32: =ROUND(6000/2.0000,0) | E32: =ROUND(6000/2.5000,0) | F32: =ROUND(6000/3.0000,0) | G32: =ROUND(6000/3.5000,0) | H32: =ROUND(6000/4.0000,0)
A33: R$ 7.000 | B33: =ROUND(7000/1.0000,0) | C33: =ROUND(7000/1.5000,0) | D33: =ROUND(7000/2.0000,0) | E33: =ROUND(7000/2.5000,0) | F33: =ROUND(7000/3.0000,0) | G33: =ROUND(7000/3.5000,0) | H33: =ROUND(7000/4.0000,0)
A34: R$ 8.000 | B34: =ROUND(8000/1.0000,0) | C34: =ROUND(8000/1.5000,0) | D34: =ROUND(8000/2.0000,0) | E34: =ROUND(8000/2.5000,0) | F34: =ROUND(8000/3.0000,0) | G34: =ROUND(8000/3.5000,0) | H34: =ROUND(8000/4.0000,0)
A35: R$ 9.000 | B35: =ROUND(9000/1.0000,0) | C35: =ROUND(9000/1.5000,0) | D35: =ROUND(9000/2.0000,0) | E35: =ROUND(9000/2.5000,0) | F35: =ROUND(9000/3.0000,0) | G35: =ROUND(9000/3.5000,0) | H35: =ROUND(9000/4.0000,0)
A36: R$ 10.000 | B36: =ROUND(10000/1.0000,0) | C36: =ROUND(10000/1.5000,0) | D36: =ROUND(10000/2.0000,0) | E36: =ROUND(10000/2.5000,0) | F36: =ROUND(10000/3.0000,0) | G36: =ROUND(10000/3.5000,0) | H36: =ROUND(10000/4.0000,0)
A38: Seu cenário atual: MC calculada em Break-Even!B7 | Custo Fixo em Break-Even!B9

Sheet Projecao
A1: PROJEÇÃO 12 MESES — Resultado Mensal e Capital de Giro
A2: Alimentado pelas Premissas — não edite esta aba
A3: Mês | B3: Ramp % | C3: Vol. Receb. | D3: Vol. Entreg. | E3: Receita (R$) | F3: Custo Var. | G3: Custo Fixo | H3: Result. Mensal | I3: Result. Acum. | J3: Status
A4: Mês 1 | B4: =Premissas!B38 | C4: =ROUND(Premissas!B34*B4,0) | D4: =ROUND(C4*(1-Premissas!B32),0) | E4: =D4*Premissas!B5+(C4-D4)*Premissas!B6 | F4: =C4*Premissas!B14 | G4: =Premissas!B28 | H4: =E4-F4-G4 | I4: =H4 | J4: =IF(H4>=0,"LUCRO","DEFICIT")
A5: Mês 2 | B5: =Premissas!B39 | C5: =ROUND(Premissas!B34*B5,0) | D5: =ROUND(C5*(1-Premissas!B32),0) | E5: =D5*Premissas!B5+(C5-D5)*Premissas!B6 | F5: =C5*Premissas!B14 | G5: =Premissas!B28 | H5: =E5-F5-G5 | I5: =I4+H5 | J5: =IF(H5>=0,"LUCRO","DEFICIT")
A6: Mês 3 | B6: =Premissas!B40 | C6: =ROUND(Premissas!B34*B6,0) | D6: =ROUND(C6*(1-Premissas!B32),0) | E6: =D6*Premissas!B5+(C6-D6)*Premissas!B6 | F6: =C6*Premissas!B14 | G6: =Premissas!B28 | H6: =E6-F6-G6 | I6: =I5+H6 | J6: =IF(H6>=0,"LUCRO","DEFICIT")
A7: Mês 4 | B7: =Premissas!B41 | C7: =ROUND(Premissas!B34*B7,0) | D7: =ROUND(C7*(1-Premissas!B32),0) | E7: =D7*Premissas!B5+(C7-D7)*Premissas!B6 | F7: =C7*Premissas!B14 | G7: =Premissas!B28 | H7: =E7-F7-G7 | I7: =I6+H7 | J7: =IF(H7>=0,"LUCRO","DEFICIT")
A8: Mês 5 | B8: =Premissas!B42 | C8: =ROUND(Premissas!B34*B8,0) | D8: =ROUND(C8*(1-Premissas!B32),0) | E8: =D8*Premissas!B5+(C8-D8)*Premissas!B6 | F8: =C8*Premissas!B14 | G8: =Premissas!B28 | H8: =E8-F8-G8 | I8: =I7+H8 | J8: =IF(H8>=0,"LUCRO","DEFICIT")
A9: Mês 6 | B9: =Premissas!B43 | C9: =ROUND(Premissas!B34*B9,0) | D9: =ROUND(C9*(1-Premissas!B32),0) | E9: =D9*Premissas!B5+(C9-D9)*Premissas!B6 | F9: =C9*Premissas!B14 | G9: =Premissas!B28 | H9: =E9-F9-G9 | I9: =I8+H9 | J9: =IF(H9>=0,"LUCRO","DEFICIT")
A10: Mês 7 | B10: =Premissas!B44 | C10: =ROUND(Premissas!B34*B10,0) | D10: =ROUND(C10*(1-Premissas!B32),0) | E10: =D10*Premissas!B5+(C10-D10)*Premissas!B6 | F10: =C10*Premissas!B14 | G10: =Premissas!B28 | H10: =E10-F10-G10 | I10: =I9+H10 | J10: =IF(H10>=0,"LUCRO","DEFICIT")
A11: Mês 8 | B11: =Premissas!B44 | C11: =ROUND(Premissas!B34*B11,0) | D11: =ROUND(C11*(1-Premissas!B32),0) | E11: =D11*Premissas!B5+(C11-D11)*Premissas!B6 | F11: =C11*Premissas!B14 | G11: =Premissas!B28 | H11: =E11-F11-G11 | I11: =I10+H11 | J11: =IF(H11>=0,"LUCRO","DEFICIT")
A12: Mês 9 | B12: =Premissas!B44 | C12: =ROUND(Premissas!B34*B12,0) | D12: =ROUND(C12*(1-Premissas!B32),0) | E12: =D12*Premissas!B5+(C12-D12)*Premissas!B6 | F12: =C12*Premissas!B14 | G12: =Premissas!B28 | H12: =E12-F12-G12 | I12: =I11+H12 | J12: =IF(H12>=0,"LUCRO","DEFICIT")
A13: Mês 10 | B13: =Premissas!B44 | C13: =ROUND(Premissas!B34*B13,0) | D13: =ROUND(C13*(1-Premissas!B32),0) | E13: =D13*Premissas!B5+(C13-D13)*Premissas!B6 | F13: =C13*Premissas!B14 | G13: =Premissas!B28 | H13: =E13-F13-G13 | I13: =I12+H13 | J13: =IF(H13>=0,"LUCRO","DEFICIT")
A14: Mês 11 | B14: =Premissas!B44 | C14: =ROUND(Premissas!B34*B14,0) | D14: =ROUND(C14*(1-Premissas!B32),0) | E14: =D14*Premissas!B5+(C14-D14)*Premissas!B6 | F14: =C14*Premissas!B14 | G14: =Premissas!B28 | H14: =E14-F14-G14 | I14: =I13+H14 | J14: =IF(H14>=0,"LUCRO","DEFICIT")
A15: Mês 12 | B15: =Premissas!B44 | C15: =ROUND(Premissas!B34*B15,0) | D15: =ROUND(C15*(1-Premissas!B32),0) | E15: =D15*Premissas!B5+(C15-D15)*Premissas!B6 | F15: =C15*Premissas!B14 | G15: =Premissas!B28 | H15: =E15-F15-G15 | I15: =I14+H15 | J15: =IF(H15>=0,"LUCRO","DEFICIT")
A16: TOTAL 12 MESES | E16: =SUM(E4:E15) | F16: =SUM(F4:F15) | G16: =SUM(G4:G15) | H16: =SUM(H4:H15) | I16: =SUM(I4:I15)
A18: CAPITAL DE GIRO — RESUMO
A19: Déficit acumulado no período de ramp-up | I19: =IFERROR(-SUMIF(H4:H15,"<0",H4:H15),0)
A20: Investimento inicial | I20: =Premissas!B48
A21: Reserva de custo fixo em caixa | I21: =Premissas!B49*Premissas!B28
A22: CAPITAL TOTAL NECESSÁRIO ANTES DE ABRIR | I22: =I19+I20+I21
