Workbook

Sheet L1
C3: L1 | AA3: Caso | AB3: kx | AC3: ky | AD3: wc | AE3: mx | AF3: my | AG3: mxe | AH3: mye | AI3: rx | AJ3: ry | AK3: rxe | AL3: rye
I4: Cargas | M4: Rigidez | P4: Momentos Fletores | AA4: 1 | AB4: =AB18^4/(1+AB18^4) -> 0.13709083 | AC4: =1-AB4 -> 0.86290917 | AD4: =5*AB4/384 -> 0.0017850369 | AE4: =AB4/8 -> 0.017136354 | AF4: =AC4*AB18^2/8 -> 0.042992902 | AG4: 0 | AH4: 0 | AI4: =AC4*AB18/2 -> 0.27239299 | AJ4: =AB4/2 -> 0.068545417 | AK4: 0 | AL4: 0
I5: fd,ser | J5: =E11+E13*E12 -> 4.6 | M5: αi | N5: =MIN(0.8+0.2*E19/80,1) -> 0.8625 | P5: Mdx | Q5: =AB23*J6*E7^2 -> 0.80795522 | AA5: 2 | AB5: =5*AB18^4/(2+5*AB18^4) -> 0.28427072 | AC5: =1-AB5 -> 0.71572928 | AD5: =2*AB5/384 -> 0.0014805767 | AE5: =AB5/14.22 -> 0.019990908 | AF5: =AC5*AB18^2/8 -> 0.035659928 | AG5: =-AB5/8 -> -0.03553384 | AH5: 0 | AI5: =AC5*AB18/2 -> 0.22593298 | AJ5: =3*AB5/8 -> 0.10660152 | AK5: 0 | AL5: =5*AB5/8 -> 0.1776692
D6: Vãos | I6: fd | J6: =(E12+E11)*IF(E16=10,1.4*MAX(1.95-0.05*E23*100,1),1.4) -> 7.91 | M6: Eci | N6: =E20*5600*E19^0.5 -> 33600 | P6: Mdy | Q6: =AB24*J6*E7^2 -> 2.0270554 | AA6: 2A | AB6: =5*AB18^-4/(2+5*AB18^-4) -> 0.94024887 | AC6: =1-AB6 -> 0.059751133 | AD6: =2*AB6/384*AB18^4 -> 0.00077800954 | AE6: =AC6*AB18^2/8/AB18^2 -> 0.0074688916 | AF6: =AB6/14.22*AB18^2 -> 0.026355113 | AG6: 0 | AH6: =-AB6/8*AB18^2 -> -0.046846214 | AI6: =3*AB6/8*AB18 -> 0.222605 | AJ6: =AC6*AB18/2/AB18 -> 0.029875566 | AK6: =5*AB6/8*AB18 -> 0.37100834 | AL6: 0 | BC6: aa | BD6: bb | BE6: cc
D7: lx | E7: =VLOOKUP(C3,Resumo!B9:N28,5,FALSE) -> 3.255 | M7: Ecs | N7: =N6*N5 -> 28980 | P7: Mdxe | Q7: =(AB25*J6*E7^2-IF(E16=10,MAX(1.95-0.05*E23*100,1)*(1.4*J12*J13+1.4*J11*E7),0)) -> -1.4361404 | AA7: 3 | AB7: =5*AB18^4/(1+5*AB18^4) -> 0.44269594 | AC7: =1-AB7 -> 0.55730406 | AD7: =AB7/384 -> 0.001152854 | AE7: =AB7/24 -> 0.018445664 | AF7: =AC7*AB18^2/8 -> 0.027766675 | AG7: =-AB7/12 -> -0.036891329 | AH7: 0 | AI7: =AC7*AB18/2 -> 0.17592317 | AJ7: 0 | AK7: 0 | AL7: =AB7/2 -> 0.22134797 | AS7: lx | AT7: ly | BB7: 0 | BC7: 0 | BD7: 0 | BE7: 0
D8: ly | E8: =VLOOKUP(C3,Resumo!B9:N28,9,FALSE) -> 2.055 | M8: D | N8: =N7*10^6*E23^3/(12*(1-0.2^2))/1000 -> 4347 | P8: Mdye | Q8: =AB26*J6*E7^2 -> -3.603091 | AA8: 3A | AB8: =5*AB18^-4/(1+5*AB18^-4) -> 0.9692044 | AC8: =1-AB8 -> 0.030795602 | AD8: =AB8/384*AB18^4 -> 0.00040098441 | AE8: =AC8*AB18^2/8/AB18^2 -> 0.0038494503 | AF8: =AB8/24*AB18^2 -> 0.01609629 | AG8: 0 | AH8: =-AB8/12*AB18^2 -> -0.032192581 | AI8: 0 | AJ8: =AC8*AB18/2/AB18 -> 0.015397801 | AK8: =AB8/2*AB18 -> 0.30594701 | AL8: 0 | AS8: 5 | AT8: 6 | BB8: =BA10 -> 71.428571 | BC8: 0 | BD8: 0 | BE8: 0
AA9: 4 | AB9: =AB18^4/(1+AB18^4) -> 0.13709083 | AC9: =1-AB9 -> 0.86290917 | AD9: =2*AB9/384 -> 0.00071401476 | AE9: =AB9/14.22 -> 0.0096407056 | AF9: =AC9*AB18^2/14.22 -> 0.024187287 | AG9: =-AB9/8 -> -0.017136354 | AH9: =-AC9*AB18^2/8 -> -0.042992902 | AI9: =3*AC9*AB18/8 -> 0.20429474 | AJ9: =3*AB9/8 -> 0.051409062 | AK9: =5*AC9*AB18/8 -> 0.34049123 | AL9: =5*AB9/8 -> 0.085681771 | BB9: =BA10 -> 71.428571 | BC9: 0 | BD9: 0 | BE9: =AT8 -> 6
D10: Carga | I10: Laje em Balanço | M10: Flecha | P10: Reações de Apoio | AA10: 5 | AB10: =2*AB18^4/(1+2*AB18^4) -> 0.24112556 | AC10: =1-AB10 -> 0.75887444 | AD10: =AB10/384 -> 0.00062793115 | AE10: =AB10/24 -> 0.010046898 | AF10: =AC10*AB18^2/14.22 -> 0.0212712 | AG10: =-AB10/12 -> -0.020093797 | AH10: =-AC10*AB18^2/8 -> -0.037809558 | AI10: =3*AC10*AB18/8 -> 0.1796644 | AJ10: 0 | AK10: =5*AC10*AB18/8 -> 0.29944066 | AL10: =AB10/2 -> 0.12056278 | AY10: =-AT11*AT12 -> -0.5 | BA10: =1000*(AY10-AY$15)/(AY$16-AY$15) -> 71.428571 | BB10: =BA11 -> 142.85714 | BC10: 0 | BD10: 0 | BE10: =BE9 -> 6
D11: gk | E11: =VLOOKUP(C3,Resumo!B9:N28,10,FALSE) -> 4.15 | I11: Pvk | J11: 2.5 | M11: W0 | N11: =AB22*J5*E7^4/N8*1000+IF(E16=10,J11*E7^3/(3*N8)*1000,0) -> 0.084816305 | P11: Rdx | Q11: =AB27*J6*E7 -> 5.2599869 | AA11: 5A | AB11: =2*AB18^-4/(1+2*AB18^-4) -> 0.92641035 | AC11: =1-AB11 -> 0.07358965 | AD11: =AB11/384*AB18^4 -> 0.00038327943 | AE11: =AC11*AB18^2/14.22/AB18^2 -> 0.0051750809 | AF11: =AB11/24*AB18^2 -> 0.015385578 | AG11: =-AC11*AB18^2/8/AB18^2 -> -0.0091987062 | AH11: =-AB11/12*AB18^2 -> -0.030771157 | AI11: 0 | AJ11: =3*AC11*AB18/8/AB18 -> 0.027596119 | AK11: =AB11/2*AB18 -> 0.29243829 | AL11: =5*AC11*AB18/8/AB18 -> 0.045993531 | AS11: eng | AT11: =MIN(AS8:AT8)/10 -> 0.5 | AY11: 0 | BA11: =1000*(AY11-AY$15)/(AY$16-AY$15) -> 142.85714 | BB11: =BA11 -> 142.85714 | BC11: =-AT15*AT11 -> -0.5 | BD11: =AT8-BC11 -> 6.5 | BE11: =AT13*AT11 -> 0
D12: qk | E12: =VLOOKUP(C3,Resumo!B9:N28,11,FALSE) -> 1.5 | I12: Phk | J12: 1 | M12: W∞ | N12: =N11*(1+E26) -> 0.29685707 | P12: Rdy | Q12: =AB28*J6*E7 -> 1.3236317 | AA12: 6 | AB12: =AB18^4/(1+AB18^4) -> 0.13709083 | AC12: =1-AB12 -> 0.86290917 | AD12: =AB12/384 -> 0.00035700738 | AE12: =AB12/24 -> 0.005712118 | AF12: =AC12*AB18^2/24 -> 0.014330967 | AG12: =-AB12/12 -> -0.011424236 | AH12: =-AC12*AB18^2/12 -> -0.028661935 | AI12: 0 | AJ12: 0 | AK12: =AC12*AB18/2 -> 0.27239299 | AL12: =AB12/2 -> 0.068545417 | AS12: a | AT12: =IF(OR(E16=1,E16=7,E16="2A",E16="3A",E16="5A"),0,1) -> 1 | AY12: =AS8 -> 5 | BA12: =1000*(AY12-AY$15)/(AY$16-AY$15) -> 857.14286 | BB12: =BA12 -> 857.14286 | BC12: =BC11 -> -0.5 | BD12: =BD11 -> 6.5 | BE12: =BE11 -> 0
D13: ψ2 | E13: 0.3 | I13: H | J13: 1.2 | M13: Wadm | N13: =IF(E16=10,E7*1000/125,MIN(E7:E8)/250*1000) -> 8.22 | P13: Rdxe | Q13: =AB29*J6*E7 -> 8.7666448 | AA13: 7 | AB13: 0 | AC13: 0 | AD13: =5/384 -> 0.013020833 | AE13: =1/8 -> 0.125 | AF13: 0 | AG13: 0 | AH13: 0 | AI13: 0 | AJ13: =1/2 -> 0.5 | AK13: 0 | AL13: 0 | AS13: b | AT13: =IF(OR(E16="2A",E16="3A",E16="5A",E16=6),1,0) -> 0 | AY13: =AS8+AT11*AT14 -> 5 | BA13: =1000*(AY13-AY$15)/(AY$16-AY$15) -> 857.14286 | BB13: =BA12 -> 857.14286 | BC13: 0 | BD13: 0 | BE13: =AT8 -> 6
M14: =IF(N13>=N12,"Ok!","Aumentar h!!!") -> Ok! | P14: Rdye | Q14: =AB30*J6*E7 -> 2.2060528 | AA14: 8 | AB14: 0 | AC14: 0 | AD14: =2/384 -> 0.0052083333 | AE14: =1/14.22 -> 0.070323488 | AF14: 0 | AG14: =-1/8 -> -0.125 | AH14: 0 | AI14: 0 | AJ14: =3/8 -> 0.375 | AK14: 0 | AL14: =5/8 -> 0.625 | AS14: c | AT14: =IF(OR(E16=1,E16=2,E16="2A",E16="3A",E16=4,E16=7,E16=8,E16=10),0,1) -> 0 | BB14: =BA13 -> 857.14286 | BC14: 0 | BD14: 0 | BE14: =AT8 -> 6
D15: Vinculação | AA15: 9 | AB15: 0 | AC15: 0 | AD15: =1/384 -> 0.0026041667 | AE15: =1/24 -> 0.041666667 | AF15: 0 | AG15: =-1/12 -> -0.083333333 | AH15: 0 | AI15: 0 | AJ15: 0 | AK15: 0 | AL15: =1/2 -> 0.5 | AS15: d | AT15: =IF(OR(E16="3A",E16="5A",E16=4,E16=5,E16=6),1,0) -> 1 | AY15: =AS40 -> -1 | AZ15: min | BB15: =BA13 -> 857.14286 | BC15: 0 | BD15: 0 | BE15: 0
D16: Caso | E16: =VLOOKUP(C3,Resumo!B9:N28,13,FALSE) -> 4 | AA16: 10 | AB16: 0 | AC16: 0 | AD16: =48/384 -> 0.125 | AE16: 0 | AF16: 0 | AG16: =-1/2 -> -0.5 | AH16: 0 | AI16: 0 | AJ16: 0 | AK16: 0 | AL16: 1 | AY16: =AS41 -> 6 | AZ16: max | BB16: 1000 | BC16: 0 | BD16: 0 | BE16: 0
D18: Concreto | AA18: λ | AB18: =E8/E7 -> 0.63133641 | AD18: x | AE18: y | AF18: =IF(AF19=0,"",Q7) | AG18: 0.8 | AI18: x | AJ18: y | AK18: =IF(E16=10,"",Q5) -> 0.80795522 | AL18: 0.8
D19: fck | E19: 25 | AD19: =(AS8-(1-AG18)/2*AS8)*AF19 -> 0 | AE19: =AT8/2 -> 3 | AF19: =IF(OR(E16=3,E16=5,E16="5A",E16=6,E16=9),1,0) -> 0 | AI19: =(AS8/2-(1-AL18)/2*AS8)*AK19 -> 2 | AJ19: =AT8/2 -> 3 | AK19: =IF(E16=10,0,1) -> 1
D20: αe | E20: 1.2 | AA20: kx | AB20: =VLOOKUP(E$16,AA$4:AL$16,2,TRUE) -> 0.13709083 | AD20: =((AS8-AD19)+AS8)*AF20 -> 0 | AE20: =AE19 -> 3 | AF20: =IF(OR(E16=3,E16=5,E16="5A",E16=6,E16=9),1,0) -> 0 | AI20: =((AS8/2-AI19)+AS8/2)*AK20 -> 3 | AJ20: =AJ19 -> 3 | AK20: =AK19 -> 1
AA21: ky | AB21: =VLOOKUP(E$16,AA$4:AL$16,3,TRUE) -> 0.86290917 | AF21: =IF(AF22=0,"",Q7) -> -1.4361404 | AS21: x | AT21: y
D22: Espessura | AA22: wc | AB22: =VLOOKUP(E$16,AA$4:AL$16,4,TRUE) -> 0.00071401476 | AD22: =-(1-AG18)/2*AS8*AF22 -> -0.5 | AE22: =AE19 -> 3 | AF22: =IF(OR(E16=1,E16="2A",E16="3A",E16="5A",E16=7),0,1) -> 1 | AI22: x | AJ22: y | AK22: =IF(OR(E16=7,E16=8,E16=9,E16=10),"",Q6) -> 2.0270554 | AL22: 0.8 | AS22: 0 | AT22: 0
D23: h | E23: 0.12 | AA23: mx | AB23: =VLOOKUP(E$16,AA$4:AL$16,5,TRUE) -> 0.0096407056 | AD23: =-AD22 -> 0.5 | AE23: =AE20 -> 3 | AF23: =IF(OR(E16=1,E16="2A",E16="3A",E16="5A",E16=7),0,1) -> 1 | AI23: =AS8/2 -> 2.5 | AJ23: =(AT8/2-(1-AL22)/2*AT8)*AK23 -> 2.4 | AK23: =IF(OR(E16=7,E16=8,E16=9,E16=10),0,1) -> 1 | AS23: =AS8 -> 5 | AT23: 0
AA24: my | AB24: =VLOOKUP(E$16,AA$4:AL$16,6,TRUE) -> 0.024187287 | AF24: =IF(AF26=0,"",Q8) | AG24: 0.8 | AI24: =AI23 -> 2.5 | AJ24: =((AT8/2-AJ23)+AT8/2)*AK23 -> 3.6 | AS24: =AS8 -> 5 | AT24: =AT8 -> 6
D25: Fluência | AA25: mxe | AB25: =VLOOKUP(E$16,AA$4:AL$16,7,TRUE) -> -0.017136354 | AD25: =AS8/2 -> 2.5 | AE25: =(AT8+(1-AG24)/2*AT8)*AF25 -> 0 | AF25: =IF(OR(E16=6,E16="2A",E16="3A",E16="5A"),1,0) -> 0 | AK25: =IF(OR(E16=1,E16=7,E16="2A",E16="3A",E16="5A"),Q12,Q14) -> 2.2060528 | AS25: 0 | AT25: =AT24 -> 6
D26: φ | E26: 2.5 | AA26: mye | AB26: =VLOOKUP(E$16,AA$4:AL$16,8,TRUE) -> -0.042992902 | AD26: =AD25 -> 2.5 | AE26: =(AT8-(AE25-AT8))*AF26 -> 0 | AF26: =IF(OR(E16=6,E16="2A",E16="3A",E16="5A"),1,0) -> 0 | AI26: 0 | AJ26: =0.4*AT8 -> 2.4 | AS26: 0 | AT26: 0
AA27: rx | AB27: =VLOOKUP(E$16,AA$4:AL$16,9,TRUE) -> 0.20429474 | AF27: =IF(AF28=0,"",Q8) -> -3.603091 | AI27: 0 | AJ27: =0.6*AT8 -> 3.6 | AS27: 0 | AT27: 0
AA28: ry | AB28: =VLOOKUP(E$16,AA$4:AL$16,10,TRUE) -> 0.051409062 | AD28: =AD25 -> 2.5 | AE28: =(1-AG24)/2*AT8*AF28 -> 0.6 | AF28: =IF(OR(E16="3A",E16="5A",E16=4,E16=5,E16=6),1,0) -> 1 | AK28: =IF(OR(E16=4,E16=5,E16=6,E16=7,E16=8,E16=9,E16=10,E16="3A",E16="5A"),Q13,Q11) -> 8.7666448 | AS28: =-AT11*AT12 -> -0.5 | AT28: 0
AA29: rxe | AB29: =VLOOKUP(E$16,AA$4:AL$16,11,TRUE) -> 0.34049123 | AD29: =AD26 -> 2.5 | AE29: =-AE28 -> -0.6 | AF29: =IF(OR(E16="3A",E16="5A",E16=4,E16=5,E16=6),1,0) -> 1 | AI29: =0.4*AS8 -> 2 | AJ29: 0 | AS29: =AS28 -> -0.5 | AT29: =AT25 -> 6
AA30: rye | AB30: =VLOOKUP(E$16,AA$4:AL$16,12,TRUE) -> 0.085681771 | AI30: =0.6*AS8 -> 3 | AJ30: 0 | AS30: 0 | AT30: =AT29 -> 6
AD31: x | AE31: y | AK31: =IF(OR(E16=3,E16=5,E16=6,E16=9,E16="5A"),Q14,Q12) -> 1.3236317 | AS31: 0 | AT31: =AT30+AT11*AT13 -> 6
AD32: 0 | AE32: 0 | AI32: =AS8 -> 5 | AJ32: =AJ23 -> 2.4 | AS32: =AS24 -> 5 | AT32: =AT31 -> 6
AD33: =AS8*AF33 -> 0 | AE33: 0 | AF33: =IF(OR(E16<7,E16="2A",E16="3A",E16="5A"),0,1) -> 0 | AI33: =AS8 -> 5 | AJ33: =AJ24 -> 3.6 | AS33: =AS32 -> 5 | AT33: =AT30 -> 6
AD34: 0 | AE34: =AT8 -> 6 | AK34: =IF(OR(E16="2A",E16="3A",E16="5A",E16=6),Q13,Q11) -> 5.2599869 | AS34: =AS33+AT14*AT11 -> 5 | AT34: =AT33 -> 6
AD35: =AD33 -> 0 | AE35: =AE34 -> 6 | AI35: =AI29 -> 2 | AJ35: =AT8 -> 6 | AS35: =AS34 -> 5 | AT35: 0
AD36: =AS8 -> 5 | AE36: 0 | AI36: =AI30 -> 3 | AJ36: =AJ35 -> 6 | AS36: =AS33 -> 5 | AT36: 0
AD37: =AS8 -> 5 | AE37: =AT8*AF37 -> 0 | AF37: =IF(E16=10,1,0) -> 0 | AS37: =AS36 -> 5 | AT37: =-AT15*AT11 -> -0.5
AS38: 0 | AT38: =AT37 -> -0.5
AS39: 0 | AT39: 0
AS40: -1 | AT40: -2
AS41: 6 | AT41: 8

Sheet L2
C3: L2 | AA3: Caso | AB3: kx | AC3: ky | AD3: wc | AE3: mx | AF3: my | AG3: mxe | AH3: mye | AI3: rx | AJ3: ry | AK3: rxe | AL3: rye
I4: Cargas | M4: Rigidez | P4: Momentos Fletores | AA4: 1 | AB4: =AB18^4/(1+AB18^4) -> 0.12051129 | AC4: =1-AB4 -> 0.87948871 | AD4: =5*AB4/384 -> 0.0015691575 | AE4: =AB4/8 -> 0.015063912 | AF4: =AC4*AB18^2/8 -> 0.04069481 | AG4: 0 | AH4: 0 | AI4: =AC4*AB18/2 -> 0.26754673 | AJ4: =AB4/2 -> 0.060255647 | AK4: 0 | AL4: 0
I5: fd,ser | J5: =E11+E13*E12 -> 4.6 | M5: αi | N5: =MIN(0.8+0.2*E19/80,1) -> 0.8625 | P5: Mdx | Q5: =AB23*J6*E7^2 -> 0.33879534 | AA5: 2 | AB5: =5*AB18^4/(2+5*AB18^4) -> 0.2551547 | AC5: =1-AB5 -> 0.7448453 | AD5: =2*AB5/384 -> 0.0013289307 | AE5: =AB5/14.22 -> 0.017943368 | AF5: =AC5*AB18^2/8 -> 0.034464726 | AG5: =-AB5/8 -> -0.031894337 | AH5: 0 | AI5: =AC5*AB18/2 -> 0.22658724 | AJ5: =3*AB5/8 -> 0.095683012 | AK5: 0 | AL5: =5*AB5/8 -> 0.15947169
D6: Vãos | I6: fd | J6: =(E12+E11)*IF(E16=10,1.4*MAX(1.95-0.05*E23*100,1),1.4) -> 7.91 | M6: Eci | N6: =E20*5600*E19^0.5 -> 33600 | P6: Mdy | Q6: =AB24*J6*E7^2 -> 0.65074117 | AA6: 2A | AB6: =5*AB18^-4/(2+5*AB18^-4) -> 0.9480383 | AC6: =1-AB6 -> 0.0519617 | AD6: =2*AB6/384*AB18^4 -> 0.00067658464 | AE6: =AC6*AB18^2/8/AB18^2 -> 0.0064952125 | AF6: =AB6/14.22*AB18^2 -> 0.024678856 | AG6: 0 | AH6: =-AB6/8*AB18^2 -> -0.043866667 | AI6: =3*AB6/8*AB18 -> 0.2163 | AJ6: =AC6*AB18/2/AB18 -> 0.02598085 | AK6: =5*AB6/8*AB18 -> 0.3605 | AL6: 0 | BC6: aa | BD6: bb | BE6: cc
D7: lx | E7: =VLOOKUP(C3,Resumo!B9:N28,5,FALSE) -> 1.545 | M7: Ecs | N7: =N6*N5 -> 28980 | P7: Mdxe | Q7: =(AB25*J6*E7^2-IF(E16=10,MAX(1.95-0.05*E23*100,1)*(1.4*J12*J13+1.4*J11*E7),0)) -> -0.60220871 | AA7: 3 | AB7: =5*AB18^4/(1+5*AB18^4) -> 0.40657092 | AC7: =1-AB7 -> 0.59342908 | AD7: =AB7/384 -> 0.0010587784 | AE7: =AB7/24 -> 0.016940455 | AF7: =AC7*AB18^2/8 -> 0.027458549 | AG7: =-AB7/12 -> -0.03388091 | AH7: 0 | AI7: =AC7*AB18/2 -> 0.18052535 | AJ7: 0 | AK7: 0 | AL7: =AB7/2 -> 0.20328546 | AS7: lx | AT7: ly | BB7: 0 | BC7: 0 | BD7: 0 | BE7: 0
D8: ly | E8: =VLOOKUP(C3,Resumo!B9:N28,9,FALSE) -> 0.94 | M8: D | N8: =N7*10^6*E23^3/(12*(1-0.2^2))/1000 -> 4347 | P8: Mdye | Q8: =AB26*J6*E7^2 -> 0 | AA8: 3A | AB8: =5*AB18^-4/(1+5*AB18^-4) -> 0.97332614 | AC8: =1-AB8 -> 0.02667386 | AD8: =AB8/384*AB18^4 -> 0.00034731588 | AE8: =AC8*AB18^2/8/AB18^2 -> 0.0033342325 | AF8: =AB8/24*AB18^2 -> 0.015012253 | AG8: 0 | AH8: =-AB8/12*AB18^2 -> -0.030024507 | AI8: 0 | AJ8: =AC8*AB18/2/AB18 -> 0.01333693 | AK8: =AB8/2*AB18 -> 0.29609274 | AL8: 0 | AS8: 5 | AT8: 6 | BB8: =BA10 -> 71.428571 | BC8: 0 | BD8: 0 | BE8: 0
AA9: 4 | AB9: =AB18^4/(1+AB18^4) -> 0.12051129 | AC9: =1-AB9 -> 0.87948871 | AD9: =2*AB9/384 -> 0.00062766299 | AE9: =AB9/14.22 -> 0.0084747745 | AF9: =AC9*AB18^2/14.22 -> 0.022894408 | AG9: =-AB9/8 -> -0.015063912 | AH9: =-AC9*AB18^2/8 -> -0.04069481 | AI9: =3*AC9*AB18/8 -> 0.20066004 | AJ9: =3*AB9/8 -> 0.045191735 | AK9: =5*AC9*AB18/8 -> 0.33443341 | AL9: =5*AB9/8 -> 0.075319558 | BB9: =BA10 -> 71.428571 | BC9: 0 | BD9: 0 | BE9: =AT8 -> 6
D10: Carga | I10: Laje em Balanço | M10: Flecha | P10: Reações de Apoio | AA10: 5 | AB10: =2*AB18^4/(1+2*AB18^4) -> 0.21510054 | AC10: =1-AB10 -> 0.78489946 | AD10: =AB10/384 -> 0.00056015766 | AE10: =AB10/24 -> 0.0089625226 | AF10: =AC10*AB18^2/14.22 -> 0.020432108 | AG10: =-AB10/12 -> -0.017925045 | AH10: =-AC10*AB18^2/8 -> -0.036318072 | AI10: =3*AC10*AB18/8 -> 0.179079 | AJ10: 0 | AK10: =5*AC10*AB18/8 -> 0.298465 | AL10: =AB10/2 -> 0.10755027 | AY10: =-AT11*AT12 -> -0.5 | BA10: =1000*(AY10-AY$15)/(AY$16-AY$15) -> 71.428571 | BB10: =BA11 -> 142.85714 | BC10: 0 | BD10: 0 | BE10: =BE9 -> 6
D11: gk | E11: =VLOOKUP(C3,Resumo!B9:N28,10,FALSE) -> 4.15 | I11: Pvk | J11: 2.5 | M11: W0 | N11: =AB22*J5*E7^4/N8*1000+IF(E16=10,J11*E7^3/(3*N8)*1000,0) -> 0.0080128031 | P11: Rdx | Q11: =AB27*J6*E7 -> 2.7691114 | AA11: 5A | AB11: =2*AB18^-4/(1+2*AB18^-4) -> 0.93588081 | AC11: =1-AB11 -> 0.06411919 | AD11: =AB11/384*AB18^4 -> 0.00033395411 | AE11: =AC11*AB18^2/14.22/AB18^2 -> 0.0045090851 | AF11: =AB11/24*AB18^2 -> 0.014434709 | AG11: =-AC11*AB18^2/8/AB18^2 -> -0.0080148987 | AH11: =-AB11/12*AB18^2 -> -0.028869418 | AI11: 0 | AJ11: =3*AC11*AB18/8/AB18 -> 0.024044696 | AK11: =AB11/2*AB18 -> 0.28470161 | AL11: =5*AC11*AB18/8/AB18 -> 0.040074494 | AS11: eng | AT11: =MIN(AS8:AT8)/10 -> 0.5 | AY11: 0 | BA11: =1000*(AY11-AY$15)/(AY$16-AY$15) -> 142.85714 | BB11: =BA11 -> 142.85714 | BC11: =-AT15*AT11 -> 0 | BD11: =AT8-BC11 -> 6 | BE11: =AT13*AT11 -> 0
D12: qk | E12: =VLOOKUP(C3,Resumo!B9:N28,11,FALSE) -> 1.5 | I12: Phk | J12: 1 | M12: W∞ | N12: =N11*(1+E26) -> 0.028044811 | P12: Rdy | Q12: =AB28*J6*E7 -> 1.1693373 | AA12: 6 | AB12: =AB18^4/(1+AB18^4) -> 0.12051129 | AC12: =1-AB12 -> 0.87948871 | AD12: =AB12/384 -> 0.00031383149 | AE12: =AB12/24 -> 0.0050213039 | AF12: =AC12*AB18^2/24 -> 0.013564937 | AG12: =-AB12/12 -> -0.010042608 | AH12: =-AC12*AB18^2/12 -> -0.027129873 | AI12: 0 | AJ12: 0 | AK12: =AC12*AB18/2 -> 0.26754673 | AL12: =AB12/2 -> 0.060255647 | AS12: a | AT12: =IF(OR(E16=1,E16=7,E16="2A",E16="3A",E16="5A"),0,1) -> 1 | AY12: =AS8 -> 5 | BA12: =1000*(AY12-AY$15)/(AY$16-AY$15) -> 857.14286 | BB12: =BA12 -> 857.14286 | BC12: =BC11 -> 0 | BD12: =BD11 -> 6 | BE12: =BE11 -> 0
D13: ψ2 | E13: 0.3 | I13: H | J13: 1.2 | M13: Wadm | N13: =IF(E16=10,E7*1000/125,MIN(E7:E8)/250*1000) -> 3.76 | P13: Rdxe | Q13: =AB29*J6*E7 -> 0 | AA13: 7 | AB13: 0 | AC13: 0 | AD13: =5/384 -> 0.013020833 | AE13: =1/8 -> 0.125 | AF13: 0 | AG13: 0 | AH13: 0 | AI13: 0 | AJ13: =1/2 -> 0.5 | AK13: 0 | AL13: 0 | AS13: b | AT13: =IF(OR(E16="2A",E16="3A",E16="5A",E16=6),1,0) -> 0 | AY13: =AS8+AT11*AT14 -> 5 | BA13: =1000*(AY13-AY$15)/(AY$16-AY$15) -> 857.14286 | BB13: =BA12 -> 857.14286 | BC13: 0 | BD13: 0 | BE13: =AT8 -> 6
M14: =IF(N13>=N12,"Ok!","Aumentar h!!!") -> Ok! | P14: Rdye | Q14: =AB30*J6*E7 -> 1.9488955 | AA14: 8 | AB14: 0 | AC14: 0 | AD14: =2/384 -> 0.0052083333 | AE14: =1/14.22 -> 0.070323488 | AF14: 0 | AG14: =-1/8 -> -0.125 | AH14: 0 | AI14: 0 | AJ14: =3/8 -> 0.375 | AK14: 0 | AL14: =5/8 -> 0.625 | AS14: c | AT14: =IF(OR(E16=1,E16=2,E16="2A",E16="3A",E16=4,E16=7,E16=8,E16=10),0,1) -> 0 | BB14: =BA13 -> 857.14286 | BC14: 0 | BD14: 0 | BE14: =AT8 -> 6
D15: Vinculação | AA15: 9 | AB15: 0 | AC15: 0 | AD15: =1/384 -> 0.0026041667 | AE15: =1/24 -> 0.041666667 | AF15: 0 | AG15: =-1/12 -> -0.083333333 | AH15: 0 | AI15: 0 | AJ15: 0 | AK15: 0 | AL15: =1/2 -> 0.5 | AS15: d | AT15: =IF(OR(E16="3A",E16="5A",E16=4,E16=5,E16=6),1,0) -> 0 | AY15: =AS40 -> -1 | AZ15: min | BB15: =BA13 -> 857.14286 | BC15: 0 | BD15: 0 | BE15: 0
D16: Caso | E16: =VLOOKUP(C3,Resumo!B9:N28,13,FALSE) -> 2 | AA16: 10 | AB16: 0 | AC16: 0 | AD16: =48/384 -> 0.125 | AE16: 0 | AF16: 0 | AG16: =-1/2 -> -0.5 | AH16: 0 | AI16: 0 | AJ16: 0 | AK16: 0 | AL16: 1 | AY16: =AS41 -> 6 | AZ16: max | BB16: 1000 | BC16: 0 | BD16: 0 | BE16: 0
D18: Concreto | AA18: λ | AB18: =E8/E7 -> 0.60841424 | AD18: x | AE18: y | AF18: =IF(AF19=0,"",Q7) | AG18: 0.8 | AI18: x | AJ18: y | AK18: =IF(E16=10,"",Q5) -> 0.33879534 | AL18: 0.8
D19: fck | E19: 25 | AD19: =(AS8-(1-AG18)/2*AS8)*AF19 -> 0 | AE19: =AT8/2 -> 3 | AF19: =IF(OR(E16=3,E16=5,E16="5A",E16=6,E16=9),1,0) -> 0 | AI19: =(AS8/2-(1-AL18)/2*AS8)*AK19 -> 2 | AJ19: =AT8/2 -> 3 | AK19: =IF(E16=10,0,1) -> 1
D20: αe | E20: 1.2 | AA20: kx | AB20: =VLOOKUP(E$16,AA$4:AL$16,2,TRUE) -> 0.2551547 | AD20: =((AS8-AD19)+AS8)*AF20 -> 0 | AE20: =AE19 -> 3 | AF20: =IF(OR(E16=3,E16=5,E16="5A",E16=6,E16=9),1,0) -> 0 | AI20: =((AS8/2-AI19)+AS8/2)*AK20 -> 3 | AJ20: =AJ19 -> 3 | AK20: =AK19 -> 1
AA21: ky | AB21: =VLOOKUP(E$16,AA$4:AL$16,3,TRUE) -> 0.7448453 | AF21: =IF(AF22=0,"",Q7) -> -0.60220871 | AS21: x | AT21: y
D22: Espessura | AA22: wc | AB22: =VLOOKUP(E$16,AA$4:AL$16,4,TRUE) -> 0.0013289307 | AD22: =-(1-AG18)/2*AS8*AF22 -> -0.5 | AE22: =AE19 -> 3 | AF22: =IF(OR(E16=1,E16="2A",E16="3A",E16="5A",E16=7),0,1) -> 1 | AI22: x | AJ22: y | AK22: =IF(OR(E16=7,E16=8,E16=9,E16=10),"",Q6) -> 0.65074117 | AL22: 0.8 | AS22: 0 | AT22: 0
D23: h | E23: 0.12 | AA23: mx | AB23: =VLOOKUP(E$16,AA$4:AL$16,5,TRUE) -> 0.017943368 | AD23: =-AD22 -> 0.5 | AE23: =AE20 -> 3 | AF23: =IF(OR(E16=1,E16="2A",E16="3A",E16="5A",E16=7),0,1) -> 1 | AI23: =AS8/2 -> 2.5 | AJ23: =(AT8/2-(1-AL22)/2*AT8)*AK23 -> 2.4 | AK23: =IF(OR(E16=7,E16=8,E16=9,E16=10),0,1) -> 1 | AS23: =AS8 -> 5 | AT23: 0
AA24: my | AB24: =VLOOKUP(E$16,AA$4:AL$16,6,TRUE) -> 0.034464726 | AF24: =IF(AF26=0,"",Q8) | AG24: 0.8 | AI24: =AI23 -> 2.5 | AJ24: =((AT8/2-AJ23)+AT8/2)*AK23 -> 3.6 | AS24: =AS8 -> 5 | AT24: =AT8 -> 6
D25: Fluência | AA25: mxe | AB25: =VLOOKUP(E$16,AA$4:AL$16,7,TRUE) -> -0.031894337 | AD25: =AS8/2 -> 2.5 | AE25: =(AT8+(1-AG24)/2*AT8)*AF25 -> 0 | AF25: =IF(OR(E16=6,E16="2A",E16="3A",E16="5A"),1,0) -> 0 | AK25: =IF(OR(E16=1,E16=7,E16="2A",E16="3A",E16="5A"),Q12,Q14) -> 1.9488955 | AS25: 0 | AT25: =AT24 -> 6
D26: φ | E26: 2.5 | AA26: mye | AB26: =VLOOKUP(E$16,AA$4:AL$16,8,TRUE) -> 0 | AD26: =AD25 -> 2.5 | AE26: =(AT8-(AE25-AT8))*AF26 -> 0 | AF26: =IF(OR(E16=6,E16="2A",E16="3A",E16="5A"),1,0) -> 0 | AI26: 0 | AJ26: =0.4*AT8 -> 2.4 | AS26: 0 | AT26: 0
AA27: rx | AB27: =VLOOKUP(E$16,AA$4:AL$16,9,TRUE) -> 0.22658724 | AF27: =IF(AF28=0,"",Q8) | AI27: 0 | AJ27: =0.6*AT8 -> 3.6 | AS27: 0 | AT27: 0
AA28: ry | AB28: =VLOOKUP(E$16,AA$4:AL$16,10,TRUE) -> 0.095683012 | AD28: =AD25 -> 2.5 | AE28: =(1-AG24)/2*AT8*AF28 -> 0 | AF28: =IF(OR(E16="3A",E16="5A",E16=4,E16=5,E16=6),1,0) -> 0 | AK28: =IF(OR(E16=4,E16=5,E16=6,E16=7,E16=8,E16=9,E16=10,E16="3A",E16="5A"),Q13,Q11) -> 2.7691114 | AS28: =-AT11*AT12 -> -0.5 | AT28: 0
AA29: rxe | AB29: =VLOOKUP(E$16,AA$4:AL$16,11,TRUE) -> 0 | AD29: =AD26 -> 2.5 | AE29: =-AE28 -> 0 | AF29: =IF(OR(E16="3A",E16="5A",E16=4,E16=5,E16=6),1,0) -> 0 | AI29: =0.4*AS8 -> 2 | AJ29: 0 | AS29: =AS28 -> -0.5 | AT29: =AT25 -> 6
AA30: rye | AB30: =VLOOKUP(E$16,AA$4:AL$16,12,TRUE) -> 0.15947169 | AI30: =0.6*AS8 -> 3 | AJ30: 0 | AS30: 0 | AT30: =AT29 -> 6
AD31: x | AE31: y | AK31: =IF(OR(E16=3,E16=5,E16=6,E16=9,E16="5A"),Q14,Q12) -> 1.1693373 | AS31: 0 | AT31: =AT30+AT11*AT13 -> 6
AD32: 0 | AE32: 0 | AI32: =AS8 -> 5 | AJ32: =AJ23 -> 2.4 | AS32: =AS24 -> 5 | AT32: =AT31 -> 6
AD33: =AS8*AF33 -> 0 | AE33: 0 | AF33: =IF(OR(E16<7,E16="2A",E16="3A",E16="5A"),0,1) -> 0 | AI33: =AS8 -> 5 | AJ33: =AJ24 -> 3.6 | AS33: =AS32 -> 5 | AT33: =AT30 -> 6
AD34: 0 | AE34: =AT8 -> 6 | AK34: =IF(OR(E16="2A",E16="3A",E16="5A",E16=6),Q13,Q11) -> 2.7691114 | AS34: =AS33+AT14*AT11 -> 5 | AT34: =AT33 -> 6
AD35: =AD33 -> 0 | AE35: =AE34 -> 6 | AI35: =AI29 -> 2 | AJ35: =AT8 -> 6 | AS35: =AS34 -> 5 | AT35: 0
AD36: =AS8 -> 5 | AE36: 0 | AI36: =AI30 -> 3 | AJ36: =AJ35 -> 6 | AS36: =AS33 -> 5 | AT36: 0
AD37: =AS8 -> 5 | AE37: =AT8*AF37 -> 0 | AF37: =IF(E16=10,1,0) -> 0 | AS37: =AS36 -> 5 | AT37: =-AT15*AT11 -> 0
AS38: 0 | AT38: =AT37 -> 0
AS39: 0 | AT39: 0
AS40: -1 | AT40: -2
AS41: 6 | AT41: 8

Sheet L3
C3: L3 | AA3: Caso | AB3: kx | AC3: ky | AD3: wc | AE3: mx | AF3: my | AG3: mxe | AH3: mye | AI3: rx | AJ3: ry | AK3: rxe | AL3: rye
I4: Cargas | M4: Rigidez | P4: Momentos Fletores | AA4: 1 | AB4: =AB18^4/(1+AB18^4) -> 0.30515273 | AC4: =1-AB4 -> 0.69484727 | AD4: =5*AB4/384 -> 0.0039733429 | AE4: =AB4/8 -> 0.038144092 | AF4: =AC4*AB18^2/8 -> 0.057559011 | AG4: 0 | AH4: 0 | AI4: =AC4*AB18/2 -> 0.28282405 | AJ4: =AB4/2 -> 0.15257637 | AK4: 0 | AL4: 0
I5: fd,ser | J5: =E11+E13*E12 -> 4.45 | M5: αi | N5: =MIN(0.8+0.2*E19/80,1) -> 0.8625 | P5: Mdx | Q5: =AB23*J6*E7^2 -> 1.2403022 | AA5: 2 | AB5: =5*AB18^4/(2+5*AB18^4) -> 0.52333581 | AC5: =1-AB5 -> 0.47666419 | AD5: =2*AB5/384 -> 0.0027257073 | AE5: =AB5/14.22 -> 0.036802799 | AF5: =AC5*AB18^2/8 -> 0.039485396 | AG5: =-AB5/8 -> -0.065416976 | AH5: 0 | AI5: =AC5*AB18/2 -> 0.19401688 | AJ5: =3*AB5/8 -> 0.19625093 | AK5: 0 | AL5: =5*AB5/8 -> 0.32708488
D6: Vãos | I6: fd | J6: =(E12+E11)*IF(E16=10,1.4*MAX(1.95-0.05*E23*100,1),1.4) -> 7.21 | M6: Eci | N6: =E20*5600*E19^0.5 -> 33600 | P6: Mdy | Q6: =AB24*J6*E7^2 -> 1.3307091 | AA6: 2A | AB6: =5*AB18^-4/(2+5*AB18^-4) -> 0.85058166 | AC6: =1-AB6 -> 0.14941834 | AD6: =2*AB6/384*AB18^4 -> 0.0019455513 | AE6: =AC6*AB18^2/8/AB18^2 -> 0.018677293 | AF6: =AB6/14.22*AB18^2 -> 0.039639701 | AG6: 0 | AH6: =-AB6/8*AB18^2 -> -0.070459569 | AI6: =3*AB6/8*AB18 -> 0.25965953 | AJ6: =AC6*AB18/2/AB18 -> 0.074709172 | AK6: =5*AB6/8*AB18 -> 0.43276588 | AL6: 0 | BC6: aa | BD6: bb | BE6: cc
D7: lx | E7: =VLOOKUP(C3,Resumo!B9:N28,5,FALSE) -> 2.162 | M7: Ecs | N7: =N6*N5 -> 28980 | P7: Mdxe | Q7: =(AB25*J6*E7^2-IF(E16=10,MAX(1.95-0.05*E23*100,1)*(1.4*J12*J13+1.4*J11*E7),0)) -> -2.2046371 | AA7: 3 | AB7: =5*AB18^4/(1+5*AB18^4) -> 0.68709185 | AC7: =1-AB7 -> 0.31290815 | AD7: =AB7/384 -> 0.0017893017 | AE7: =AB7/24 -> 0.028628827 | AF7: =AC7*AB18^2/8 -> 0.025920349 | AG7: =-AB7/12 -> -0.057257654 | AH7: 0 | AI7: =AC7*AB18/2 -> 0.12736317 | AJ7: 0 | AK7: 0 | AL7: =AB7/2 -> 0.34354592 | AS7: lx | AT7: ly | BB7: 0 | BC7: 0 | BD7: 0 | BE7: 0
D8: ly | E8: =VLOOKUP(C3,Resumo!B9:N28,9,FALSE) -> 1.76 | M8: D | N8: =N7*10^6*E23^3/(12*(1-0.2^2))/1000 -> 4347 | P8: Mdye | Q8: =AB26*J6*E7^2 -> 0 | AA8: 3A | AB8: =5*AB18^-4/(1+5*AB18^-4) -> 0.91925871 | AC8: =1-AB8 -> 0.080741286 | AD8: =AB8/384*AB18^4 -> 0.0010513188 | AE8: =AC8*AB18^2/8/AB18^2 -> 0.010092661 | AF8: =AB8/24*AB18^2 -> 0.025382855 | AG8: 0 | AH8: =-AB8/12*AB18^2 -> -0.05076571 | AI8: 0 | AJ8: =AC8*AB18/2/AB18 -> 0.040370643 | AK8: =AB8/2*AB18 -> 0.37416636 | AL8: 0 | AS8: 5 | AT8: 6 | BB8: =BA10 -> 71.428571 | BC8: 0 | BD8: 0 | BE8: 0
AA9: 4 | AB9: =AB18^4/(1+AB18^4) -> 0.30515273 | AC9: =1-AB9 -> 0.69484727 | AD9: =2*AB9/384 -> 0.0015893372 | AE9: =AB9/14.22 -> 0.021459405 | AF9: =AC9*AB18^2/14.22 -> 0.032382003 | AG9: =-AB9/8 -> -0.038144092 | AH9: =-AC9*AB18^2/8 -> -0.057559011 | AI9: =3*AC9*AB18/8 -> 0.21211804 | AJ9: =3*AB9/8 -> 0.11443228 | AK9: =5*AC9*AB18/8 -> 0.35353006 | AL9: =5*AB9/8 -> 0.19072046 | BB9: =BA10 -> 71.428571 | BC9: 0 | BD9: 0 | BE9: =AT8 -> 6
D10: Carga | I10: Laje em Balanço | M10: Flecha | P10: Reações de Apoio | AA10: 5 | AB10: =2*AB18^4/(1+2*AB18^4) -> 0.4676123 | AC10: =1-AB10 -> 0.5323877 | AD10: =AB10/384 -> 0.0012177404 | AE10: =AB10/24 -> 0.019483846 | AF10: =AC10*AB18^2/14.22 -> 0.024810892 | AG10: =-AB10/12 -> -0.038967691 | AH10: =-AC10*AB18^2/8 -> -0.04410136 | AI10: =3*AC10*AB18/8 -> 0.16252354 | AJ10: 0 | AK10: =5*AC10*AB18/8 -> 0.27087256 | AL10: =AB10/2 -> 0.23380615 | AY10: =-AT11*AT12 -> -0.5 | BA10: =1000*(AY10-AY$15)/(AY$16-AY$15) -> 71.428571 | BB10: =BA11 -> 142.85714 | BC10: 0 | BD10: 0 | BE10: =BE9 -> 6
D11: gk | E11: =VLOOKUP(C3,Resumo!B9:N28,10,FALSE) -> 4.15 | I11: Pvk | J11: 2.5 | M11: W0 | N11: =AB22*J5*E7^4/N8*1000+IF(E16=10,J11*E7^3/(3*N8)*1000,0) -> 0.060963845 | P11: Rdx | Q11: =AB27*J6*E7 -> 3.024339 | AA11: 5A | AB11: =2*AB18^-4/(1+2*AB18^-4) -> 0.81995266 | AC11: =1-AB11 -> 0.18004734 | AD11: =AB11/384*AB18^4 -> 0.00093774654 | AE11: =AC11*AB18^2/14.22/AB18^2 -> 0.012661557 | AF11: =AB11/24*AB18^2 -> 0.022640786 | AG11: =-AC11*AB18^2/8/AB18^2 -> -0.022505917 | AH11: =-AB11/12*AB18^2 -> -0.045281572 | AI11: 0 | AJ11: =3*AC11*AB18/8/AB18 -> 0.067517751 | AK11: =AB11/2*AB18 -> 0.33374577 | AL11: =5*AC11*AB18/8/AB18 -> 0.11252958 | AS11: eng | AT11: =MIN(AS8:AT8)/10 -> 0.5 | AY11: 0 | BA11: =1000*(AY11-AY$15)/(AY$16-AY$15) -> 142.85714 | BB11: =BA11 -> 142.85714 | BC11: =-AT15*AT11 -> 0 | BD11: =AT8-BC11 -> 6 | BE11: =AT13*AT11 -> 0
D12: qk | E12: =VLOOKUP(C3,Resumo!B9:N28,11,FALSE) -> 1 | I12: Phk | J12: 1 | M12: W∞ | N12: =N11*(1+E26) -> 0.21337346 | P12: Rdy | Q12: =AB28*J6*E7 -> 3.0591634 | AA12: 6 | AB12: =AB18^4/(1+AB18^4) -> 0.30515273 | AC12: =1-AB12 -> 0.69484727 | AD12: =AB12/384 -> 0.00079466858 | AE12: =AB12/24 -> 0.012714697 | AF12: =AC12*AB18^2/24 -> 0.019186337 | AG12: =-AB12/12 -> -0.025429395 | AH12: =-AC12*AB18^2/12 -> -0.038372674 | AI12: 0 | AJ12: 0 | AK12: =AC12*AB18/2 -> 0.28282405 | AL12: =AB12/2 -> 0.15257637 | AS12: a | AT12: =IF(OR(E16=1,E16=7,E16="2A",E16="3A",E16="5A"),0,1) -> 1 | AY12: =AS8 -> 5 | BA12: =1000*(AY12-AY$15)/(AY$16-AY$15) -> 857.14286 | BB12: =BA12 -> 857.14286 | BC12: =BC11 -> 0 | BD12: =BD11 -> 6 | BE12: =BE11 -> 0
D13: ψ2 | E13: 0.3 | I13: H | J13: 1.2 | M13: Wadm | N13: =IF(E16=10,E7*1000/125,MIN(E7:E8)/250*1000) -> 7.04 | P13: Rdxe | Q13: =AB29*J6*E7 -> 0 | AA13: 7 | AB13: 0 | AC13: 0 | AD13: =5/384 -> 0.013020833 | AE13: =1/8 -> 0.125 | AF13: 0 | AG13: 0 | AH13: 0 | AI13: 0 | AJ13: =1/2 -> 0.5 | AK13: 0 | AL13: 0 | AS13: b | AT13: =IF(OR(E16="2A",E16="3A",E16="5A",E16=6),1,0) -> 0 | AY13: =AS8+AT11*AT14 -> 5 | BA13: =1000*(AY13-AY$15)/(AY$16-AY$15) -> 857.14286 | BB13: =BA12 -> 857.14286 | BC13: 0 | BD13: 0 | BE13: =AT8 -> 6
M14: =IF(N13>=N12,"Ok!","Aumentar h!!!") -> Ok! | P14: Rdye | Q14: =AB30*J6*E7 -> 5.0986056 | AA14: 8 | AB14: 0 | AC14: 0 | AD14: =2/384 -> 0.0052083333 | AE14: =1/14.22 -> 0.070323488 | AF14: 0 | AG14: =-1/8 -> -0.125 | AH14: 0 | AI14: 0 | AJ14: =3/8 -> 0.375 | AK14: 0 | AL14: =5/8 -> 0.625 | AS14: c | AT14: =IF(OR(E16=1,E16=2,E16="2A",E16="3A",E16=4,E16=7,E16=8,E16=10),0,1) -> 0 | BB14: =BA13 -> 857.14286 | BC14: 0 | BD14: 0 | BE14: =AT8 -> 6
D15: Vinculação | AA15: 9 | AB15: 0 | AC15: 0 | AD15: =1/384 -> 0.0026041667 | AE15: =1/24 -> 0.041666667 | AF15: 0 | AG15: =-1/12 -> -0.083333333 | AH15: 0 | AI15: 0 | AJ15: 0 | AK15: 0 | AL15: =1/2 -> 0.5 | AS15: d | AT15: =IF(OR(E16="3A",E16="5A",E16=4,E16=5,E16=6),1,0) -> 0 | AY15: =AS40 -> -1 | AZ15: min | BB15: =BA13 -> 857.14286 | BC15: 0 | BD15: 0 | BE15: 0
D16: Caso | E16: =VLOOKUP(C3,Resumo!B9:N28,13,FALSE) -> 2 | AA16: 10 | AB16: 0 | AC16: 0 | AD16: =48/384 -> 0.125 | AE16: 0 | AF16: 0 | AG16: =-1/2 -> -0.5 | AH16: 0 | AI16: 0 | AJ16: 0 | AK16: 0 | AL16: 1 | AY16: =AS41 -> 6 | AZ16: max | BB16: 1000 | BC16: 0 | BD16: 0 | BE16: 0
D18: Concreto | AA18: λ | AB18: =E8/E7 -> 0.81406105 | AD18: x | AE18: y | AF18: =IF(AF19=0,"",Q7) | AG18: 0.8 | AI18: x | AJ18: y | AK18: =IF(E16=10,"",Q5) -> 1.2403022 | AL18: 0.8
D19: fck | E19: 25 | AD19: =(AS8-(1-AG18)/2*AS8)*AF19 -> 0 | AE19: =AT8/2 -> 3 | AF19: =IF(OR(E16=3,E16=5,E16="5A",E16=6,E16=9),1,0) -> 0 | AI19: =(AS8/2-(1-AL18)/2*AS8)*AK19 -> 2 | AJ19: =AT8/2 -> 3 | AK19: =IF(E16=10,0,1) -> 1
D20: αe | E20: 1.2 | AA20: kx | AB20: =VLOOKUP(E$16,AA$4:AL$16,2,TRUE) -> 0.52333581 | AD20: =((AS8-AD19)+AS8)*AF20 -> 0 | AE20: =AE19 -> 3 | AF20: =IF(OR(E16=3,E16=5,E16="5A",E16=6,E16=9),1,0) -> 0 | AI20: =((AS8/2-AI19)+AS8/2)*AK20 -> 3 | AJ20: =AJ19 -> 3 | AK20: =AK19 -> 1
AA21: ky | AB21: =VLOOKUP(E$16,AA$4:AL$16,3,TRUE) -> 0.47666419 | AF21: =IF(AF22=0,"",Q7) -> -2.2046371 | AS21: x | AT21: y
D22: Espessura | AA22: wc | AB22: =VLOOKUP(E$16,AA$4:AL$16,4,TRUE) -> 0.0027257073 | AD22: =-(1-AG18)/2*AS8*AF22 -> -0.5 | AE22: =AE19 -> 3 | AF22: =IF(OR(E16=1,E16="2A",E16="3A",E16="5A",E16=7),0,1) -> 1 | AI22: x | AJ22: y | AK22: =IF(OR(E16=7,E16=8,E16=9,E16=10),"",Q6) -> 1.3307091 | AL22: 0.8 | AS22: 0 | AT22: 0
D23: h | E23: 0.12 | AA23: mx | AB23: =VLOOKUP(E$16,AA$4:AL$16,5,TRUE) -> 0.036802799 | AD23: =-AD22 -> 0.5 | AE23: =AE20 -> 3 | AF23: =IF(OR(E16=1,E16="2A",E16="3A",E16="5A",E16=7),0,1) -> 1 | AI23: =AS8/2 -> 2.5 | AJ23: =(AT8/2-(1-AL22)/2*AT8)*AK23 -> 2.4 | AK23: =IF(OR(E16=7,E16=8,E16=9,E16=10),0,1) -> 1 | AS23: =AS8 -> 5 | AT23: 0
AA24: my | AB24: =VLOOKUP(E$16,AA$4:AL$16,6,TRUE) -> 0.039485396 | AF24: =IF(AF26=0,"",Q8) | AG24: 0.8 | AI24: =AI23 -> 2.5 | AJ24: =((AT8/2-AJ23)+AT8/2)*AK23 -> 3.6 | AS24: =AS8 -> 5 | AT24: =AT8 -> 6
D25: Fluência | AA25: mxe | AB25: =VLOOKUP(E$16,AA$4:AL$16,7,TRUE) -> -0.065416976 | AD25: =AS8/2 -> 2.5 | AE25: =(AT8+(1-AG24)/2*AT8)*AF25 -> 0 | AF25: =IF(OR(E16=6,E16="2A",E16="3A",E16="5A"),1,0) -> 0 | AK25: =IF(OR(E16=1,E16=7,E16="2A",E16="3A",E16="5A"),Q12,Q14) -> 5.0986056 | AS25: 0 | AT25: =AT24 -> 6
D26: φ | E26: 2.5 | AA26: mye | AB26: =VLOOKUP(E$16,AA$4:AL$16,8,TRUE) -> 0 | AD26: =AD25 -> 2.5 | AE26: =(AT8-(AE25-AT8))*AF26 -> 0 | AF26: =IF(OR(E16=6,E16="2A",E16="3A",E16="5A"),1,0) -> 0 | AI26: 0 | AJ26: =0.4*AT8 -> 2.4 | AS26: 0 | AT26: 0
AA27: rx | AB27: =VLOOKUP(E$16,AA$4:AL$16,9,TRUE) -> 0.19401688 | AF27: =IF(AF28=0,"",Q8) | AI27: 0 | AJ27: =0.6*AT8 -> 3.6 | AS27: 0 | AT27: 0
AA28: ry | AB28: =VLOOKUP(E$16,AA$4:AL$16,10,TRUE) -> 0.19625093 | AD28: =AD25 -> 2.5 | AE28: =(1-AG24)/2*AT8*AF28 -> 0 | AF28: =IF(OR(E16="3A",E16="5A",E16=4,E16=5,E16=6),1,0) -> 0 | AK28: =IF(OR(E16=4,E16=5,E16=6,E16=7,E16=8,E16=9,E16=10,E16="3A",E16="5A"),Q13,Q11) -> 3.024339 | AS28: =-AT11*AT12 -> -0.5 | AT28: 0
AA29: rxe | AB29: =VLOOKUP(E$16,AA$4:AL$16,11,TRUE) -> 0 | AD29: =AD26 -> 2.5 | AE29: =-AE28 -> 0 | AF29: =IF(OR(E16="3A",E16="5A",E16=4,E16=5,E16=6),1,0) -> 0 | AI29: =0.4*AS8 -> 2 | AJ29: 0 | AS29: =AS28 -> -0.5 | AT29: =AT25 -> 6
AA30: rye | AB30: =VLOOKUP(E$16,AA$4:AL$16,12,TRUE) -> 0.32708488 | AI30: =0.6*AS8 -> 3 | AJ30: 0 | AS30: 0 | AT30: =AT29 -> 6
AD31: x | AE31: y | AK31: =IF(OR(E16=3,E16=5,E16=6,E16=9,E16="5A"),Q14,Q12) -> 3.0591634 | AS31: 0 | AT31: =AT30+AT11*AT13 -> 6
AD32: 0 | AE32: 0 | AI32: =AS8 -> 5 | AJ32: =AJ23 -> 2.4 | AS32: =AS24 -> 5 | AT32: =AT31 -> 6
AD33: =AS8*AF33 -> 0 | AE33: 0 | AF33: =IF(OR(E16<7,E16="2A",E16="3A",E16="5A"),0,1) -> 0 | AI33: =AS8 -> 5 | AJ33: =AJ24 -> 3.6 | AS33: =AS32 -> 5 | AT33: =AT30 -> 6
AD34: 0 | AE34: =AT8 -> 6 | AK34: =IF(OR(E16="2A",E16="3A",E16="5A",E16=6),Q13,Q11) -> 3.024339 | AS34: =AS33+AT14*AT11 -> 5 | AT34: =AT33 -> 6
AD35: =AD33 -> 0 | AE35: =AE34 -> 6 | AI35: =AI29 -> 2 | AJ35: =AT8 -> 6 | AS35: =AS34 -> 5 | AT35: 0
AD36: =AS8 -> 5 | AE36: 0 | AI36: =AI30 -> 3 | AJ36: =AJ35 -> 6 | AS36: =AS33 -> 5 | AT36: 0
AD37: =AS8 -> 5 | AE37: =AT8*AF37 -> 0 | AF37: =IF(E16=10,1,0) -> 0 | AS37: =AS36 -> 5 | AT37: =-AT15*AT11 -> 0
AS38: 0 | AT38: =AT37 -> 0
AS39: 0 | AT39: 0
AS40: -1 | AT40: -2
AS41: 6 | AT41: 8

Sheet L4
C3: L4 | AA3: Caso | AB3: kx | AC3: ky | AD3: wc | AE3: mx | AF3: my | AG3: mxe | AH3: mye | AI3: rx | AJ3: ry | AK3: rxe | AL3: rye
I4: Cargas | M4: Rigidez | P4: Momentos Fletores | AA4: 1 | AB4: =AB18^4/(1+AB18^4) -> 0 | AC4: =1-AB4 -> 1 | AD4: =5*AB4/384 -> 0 | AE4: =AB4/8 -> 0 | AF4: =AC4*AB18^2/8 -> 0 | AG4: 0 | AH4: 0 | AI4: =AC4*AB18/2 -> 0 | AJ4: =AB4/2 -> 0 | AK4: 0 | AL4: 0
I5: fd,ser | J5: =E11+E13*E12 -> 4.6 | M5: αi | N5: =MIN(0.8+0.2*E19/80,1) -> 0.8625 | P5: Mdx | Q5: =AB23*J6*E7^2 -> 0.25215597 | AA5: 2 | AB5: =5*AB18^4/(2+5*AB18^4) -> 0 | AC5: =1-AB5 -> 1 | AD5: =2*AB5/384 -> 0 | AE5: =AB5/14.22 -> 0 | AF5: =AC5*AB18^2/8 -> 0 | AG5: =-AB5/8 -> 0 | AH5: 0 | AI5: =AC5*AB18/2 -> 0 | AJ5: =3*AB5/8 -> 0 | AK5: 0 | AL5: =5*AB5/8 -> 0
D6: Vãos | I6: fd | J6: =(E12+E11)*IF(E16=10,1.4*MAX(1.95-0.05*E23*100,1),1.4) -> 7.91 | M6: Eci | N6: =E20*5600*E19^0.5 -> 33600 | P6: Mdy | Q6: =AB24*J6*E7^2 -> 0 | AA6: 2A | AB6: =5*AB18^-4/(2+5*AB18^-4) -> #DIV/0! | AC6: =1-AB6 -> #DIV/0! | AD6: =2*AB6/384*AB18^4 -> #DIV/0! | AE6: =AC6*AB18^2/8/AB18^2 -> #DIV/0! | AF6: =AB6/14.22*AB18^2 -> #DIV/0! | AG6: 0 | AH6: =-AB6/8*AB18^2 -> #DIV/0! | AI6: =3*AB6/8*AB18 -> #DIV/0! | AJ6: =AC6*AB18/2/AB18 -> #DIV/0! | AK6: =5*AB6/8*AB18 -> #DIV/0! | AL6: 0 | BC6: aa | BD6: bb | BE6: cc
D7: lx | E7: =VLOOKUP(C3,Resumo!B9:N28,5,FALSE) -> 0.505 | M7: Ecs | N7: =N6*N5 -> 28980 | P7: Mdxe | Q7: =(AB25*J6*E7^2-IF(E16=10,MAX(1.95-0.05*E23*100,1)*(1.4*J12*J13+1.4*J11*E7),0)) -> 0 | AA7: 3 | AB7: =5*AB18^4/(1+5*AB18^4) -> 0 | AC7: =1-AB7 -> 1 | AD7: =AB7/384 -> 0 | AE7: =AB7/24 -> 0 | AF7: =AC7*AB18^2/8 -> 0 | AG7: =-AB7/12 -> 0 | AH7: 0 | AI7: =AC7*AB18/2 -> 0 | AJ7: 0 | AK7: 0 | AL7: =AB7/2 -> 0 | AS7: lx | AT7: ly | BB7: 0 | BC7: 0 | BD7: 0 | BE7: 0
D8: ly | M8: D | N8: =N7*10^6*E23^3/(12*(1-0.2^2))/1000 -> 4347 | P8: Mdye | Q8: =AB26*J6*E7^2 -> 0 | AA8: 3A | AB8: =5*AB18^-4/(1+5*AB18^-4) -> #DIV/0! | AC8: =1-AB8 -> #DIV/0! | AD8: =AB8/384*AB18^4 -> #DIV/0! | AE8: =AC8*AB18^2/8/AB18^2 -> #DIV/0! | AF8: =AB8/24*AB18^2 -> #DIV/0! | AG8: 0 | AH8: =-AB8/12*AB18^2 -> #DIV/0! | AI8: 0 | AJ8: =AC8*AB18/2/AB18 -> #DIV/0! | AK8: =AB8/2*AB18 -> #DIV/0! | AL8: 0 | AS8: 5 | AT8: 6 | BB8: =BA10 -> 142.85714 | BC8: 0 | BD8: 0 | BE8: 0
AA9: 4 | AB9: =AB18^4/(1+AB18^4) -> 0 | AC9: =1-AB9 -> 1 | AD9: =2*AB9/384 -> 0 | AE9: =AB9/14.22 -> 0 | AF9: =AC9*AB18^2/14.22 -> 0 | AG9: =-AB9/8 -> 0 | AH9: =-AC9*AB18^2/8 -> 0 | AI9: =3*AC9*AB18/8 -> 0 | AJ9: =3*AB9/8 -> 0 | AK9: =5*AC9*AB18/8 -> 0 | AL9: =5*AB9/8 -> 0 | BB9: =BA10 -> 142.85714 | BC9: 0 | BD9: 0 | BE9: =AT8 -> 6
D10: Carga | I10: Laje em Balanço | M10: Flecha | P10: Reações de Apoio | AA10: 5 | AB10: =2*AB18^4/(1+2*AB18^4) -> 0 | AC10: =1-AB10 -> 1 | AD10: =AB10/384 -> 0 | AE10: =AB10/24 -> 0 | AF10: =AC10*AB18^2/14.22 -> 0 | AG10: =-AB10/12 -> 0 | AH10: =-AC10*AB18^2/8 -> 0 | AI10: =3*AC10*AB18/8 -> 0 | AJ10: 0 | AK10: =5*AC10*AB18/8 -> 0 | AL10: =AB10/2 -> 0 | AY10: =-AT11*AT12 -> 0 | BA10: =1000*(AY10-AY$15)/(AY$16-AY$15) -> 142.85714 | BB10: =BA11 -> 142.85714 | BC10: 0 | BD10: 0 | BE10: =BE9 -> 6
D11: gk | E11: =VLOOKUP(C3,Resumo!B9:N28,10,FALSE) -> 4.15 | I11: Pvk | J11: 2.5 | M11: W0 | N11: =AB22*J5*E7^4/N8*1000+IF(E16=10,J11*E7^3/(3*N8)*1000,0) -> 0.00089613303 | P11: Rdx | Q11: =AB27*J6*E7 -> 0 | AA11: 5A | AB11: =2*AB18^-4/(1+2*AB18^-4) -> #DIV/0! | AC11: =1-AB11 -> #DIV/0! | AD11: =AB11/384*AB18^4 -> #DIV/0! | AE11: =AC11*AB18^2/14.22/AB18^2 -> #DIV/0! | AF11: =AB11/24*AB18^2 -> #DIV/0! | AG11: =-AC11*AB18^2/8/AB18^2 -> #DIV/0! | AH11: =-AB11/12*AB18^2 -> #DIV/0! | AI11: 0 | AJ11: =3*AC11*AB18/8/AB18 -> #DIV/0! | AK11: =AB11/2*AB18 -> #DIV/0! | AL11: =5*AC11*AB18/8/AB18 -> #DIV/0! | AS11: eng | AT11: =MIN(AS8:AT8)/10 -> 0.5 | AY11: 0 | BA11: =1000*(AY11-AY$15)/(AY$16-AY$15) -> 142.85714 | BB11: =BA11 -> 142.85714 | BC11: =-AT15*AT11 -> 0 | BD11: =AT8-BC11 -> 6 | BE11: =AT13*AT11 -> 0
D12: qk | E12: =VLOOKUP(C3,Resumo!B9:N28,11,FALSE) -> 1.5 | I12: Phk | J12: 1 | M12: W∞ | N12: =N11*(1+E26) -> 0.0031364656 | P12: Rdy | Q12: =AB28*J6*E7 -> 1.997275 | AA12: 6 | AB12: =AB18^4/(1+AB18^4) -> 0 | AC12: =1-AB12 -> 1 | AD12: =AB12/384 -> 0 | AE12: =AB12/24 -> 0 | AF12: =AC12*AB18^2/24 -> 0 | AG12: =-AB12/12 -> 0 | AH12: =-AC12*AB18^2/12 -> 0 | AI12: 0 | AJ12: 0 | AK12: =AC12*AB18/2 -> 0 | AL12: =AB12/2 -> 0 | AS12: a | AT12: =IF(OR(E16=1,E16=7,E16="2A",E16="3A",E16="5A"),0,1) -> 0 | AY12: =AS8 -> 5 | BA12: =1000*(AY12-AY$15)/(AY$16-AY$15) -> 857.14286 | BB12: =BA12 -> 857.14286 | BC12: =BC11 -> 0 | BD12: =BD11 -> 6 | BE12: =BE11 -> 0
D13: ψ2 | E13: 0.3 | I13: H | J13: 1.2 | M13: Wadm | N13: =IF(E16=10,E7*1000/125,MIN(E7:E8)/250*1000) -> 2.02 | P13: Rdxe | Q13: =AB29*J6*E7 -> 0 | AA13: 7 | AB13: 0 | AC13: 0 | AD13: =5/384 -> 0.013020833 | AE13: =1/8 -> 0.125 | AF13: 0 | AG13: 0 | AH13: 0 | AI13: 0 | AJ13: =1/2 -> 0.5 | AK13: 0 | AL13: 0 | AS13: b | AT13: =IF(OR(E16="2A",E16="3A",E16="5A",E16=6),1,0) -> 0 | AY13: =AS8+AT11*AT14 -> 5 | BA13: =1000*(AY13-AY$15)/(AY$16-AY$15) -> 857.14286 | BB13: =BA12 -> 857.14286 | BC13: 0 | BD13: 0 | BE13: =AT8 -> 6
M14: =IF(N13>=N12,"Ok!","Aumentar h!!!") -> Ok! | P14: Rdye | Q14: =AB30*J6*E7 -> 0 | AA14: 8 | AB14: 0 | AC14: 0 | AD14: =2/384 -> 0.0052083333 | AE14: =1/14.22 -> 0.070323488 | AF14: 0 | AG14: =-1/8 -> -0.125 | AH14: 0 | AI14: 0 | AJ14: =3/8 -> 0.375 | AK14: 0 | AL14: =5/8 -> 0.625 | AS14: c | AT14: =IF(OR(E16=1,E16=2,E16="2A",E16="3A",E16=4,E16=7,E16=8,E16=10),0,1) -> 0 | BB14: =BA13 -> 857.14286 | BC14: 0 | BD14: 0 | BE14: =AT8 -> 6
D15: Vinculação | AA15: 9 | AB15: 0 | AC15: 0 | AD15: =1/384 -> 0.0026041667 | AE15: =1/24 -> 0.041666667 | AF15: 0 | AG15: =-1/12 -> -0.083333333 | AH15: 0 | AI15: 0 | AJ15: 0 | AK15: 0 | AL15: =1/2 -> 0.5 | AS15: d | AT15: =IF(OR(E16="3A",E16="5A",E16=4,E16=5,E16=6),1,0) -> 0 | AY15: =AS40 -> -1 | AZ15: min | BB15: =BA13 -> 857.14286 | BC15: 0 | BD15: 0 | BE15: 0
D16: Caso | E16: =VLOOKUP(C3,Resumo!B9:N28,13,FALSE) -> 7 | AA16: 10 | AB16: 0 | AC16: 0 | AD16: =48/384 -> 0.125 | AE16: 0 | AF16: 0 | AG16: =-1/2 -> -0.5 | AH16: 0 | AI16: 0 | AJ16: 0 | AK16: 0 | AL16: 1 | AY16: =AS41 -> 6 | AZ16: max | BB16: 1000 | BC16: 0 | BD16: 0 | BE16: 0
D18: Concreto | AA18: λ | AB18: =E8/E7 -> 0 | AD18: x | AE18: y | AF18: =IF(AF19=0,"",Q7) | AG18: 0.8 | AI18: x | AJ18: y | AK18: =IF(E16=10,"",Q5) -> 0.25215597 | AL18: 0.8
D19: fck | E19: 25 | AD19: =(AS8-(1-AG18)/2*AS8)*AF19 -> 0 | AE19: =AT8/2 -> 3 | AF19: =IF(OR(E16=3,E16=5,E16="5A",E16=6,E16=9),1,0) -> 0 | AI19: =(AS8/2-(1-AL18)/2*AS8)*AK19 -> 2 | AJ19: =AT8/2 -> 3 | AK19: =IF(E16=10,0,1) -> 1
D20: αe | E20: 1.2 | AA20: kx | AB20: =VLOOKUP(E$16,AA$4:AL$16,2,TRUE) -> 0 | AD20: =((AS8-AD19)+AS8)*AF20 -> 0 | AE20: =AE19 -> 3 | AF20: =IF(OR(E16=3,E16=5,E16="5A",E16=6,E16=9),1,0) -> 0 | AI20: =((AS8/2-AI19)+AS8/2)*AK20 -> 3 | AJ20: =AJ19 -> 3 | AK20: =AK19 -> 1
AA21: ky | AB21: =VLOOKUP(E$16,AA$4:AL$16,3,TRUE) -> 0 | AF21: =IF(AF22=0,"",Q7) | AS21: x | AT21: y
D22: Espessura | AA22: wc | AB22: =VLOOKUP(E$16,AA$4:AL$16,4,TRUE) -> 0.013020833 | AD22: =-(1-AG18)/2*AS8*AF22 -> 0 | AE22: =AE19 -> 3 | AF22: =IF(OR(E16=1,E16="2A",E16="3A",E16="5A",E16=7),0,1) -> 0 | AI22: x | AJ22: y | AK22: =IF(OR(E16=7,E16=8,E16=9,E16=10),"",Q6) | AL22: 0.8 | AS22: 0 | AT22: 0
D23: h | E23: 0.12 | AA23: mx | AB23: =VLOOKUP(E$16,AA$4:AL$16,5,TRUE) -> 0.125 | AD23: =-AD22 -> 0 | AE23: =AE20 -> 3 | AF23: =IF(OR(E16=1,E16="2A",E16="3A",E16="5A",E16=7),0,1) -> 0 | AI23: =AS8/2 -> 2.5 | AJ23: =(AT8/2-(1-AL22)/2*AT8)*AK23 -> 0 | AK23: =IF(OR(E16=7,E16=8,E16=9,E16=10),0,1) -> 0 | AS23: =AS8 -> 5 | AT23: 0
AA24: my | AB24: =VLOOKUP(E$16,AA$4:AL$16,6,TRUE) -> 0 | AF24: =IF(AF26=0,"",Q8) | AG24: 0.8 | AI24: =AI23 -> 2.5 | AJ24: =((AT8/2-AJ23)+AT8/2)*AK23 -> 0 | AS24: =AS8 -> 5 | AT24: =AT8 -> 6
D25: Fluência | AA25: mxe | AB25: =VLOOKUP(E$16,AA$4:AL$16,7,TRUE) -> 0 | AD25: =AS8/2 -> 2.5 | AE25: =(AT8+(1-AG24)/2*AT8)*AF25 -> 0 | AF25: =IF(OR(E16=6,E16="2A",E16="3A",E16="5A"),1,0) -> 0 | AK25: =IF(OR(E16=1,E16=7,E16="2A",E16="3A",E16="5A"),Q12,Q14) -> 1.997275 | AS25: 0 | AT25: =AT24 -> 6
D26: φ | E26: 2.5 | AA26: mye | AB26: =VLOOKUP(E$16,AA$4:AL$16,8,TRUE) -> 0 | AD26: =AD25 -> 2.5 | AE26: =(AT8-(AE25-AT8))*AF26 -> 0 | AF26: =IF(OR(E16=6,E16="2A",E16="3A",E16="5A"),1,0) -> 0 | AI26: 0 | AJ26: =0.4*AT8 -> 2.4 | AS26: 0 | AT26: 0
AA27: rx | AB27: =VLOOKUP(E$16,AA$4:AL$16,9,TRUE) -> 0 | AF27: =IF(AF28=0,"",Q8) | AI27: 0 | AJ27: =0.6*AT8 -> 3.6 | AS27: 0 | AT27: 0
AA28: ry | AB28: =VLOOKUP(E$16,AA$4:AL$16,10,TRUE) -> 0.5 | AD28: =AD25 -> 2.5 | AE28: =(1-AG24)/2*AT8*AF28 -> 0 | AF28: =IF(OR(E16="3A",E16="5A",E16=4,E16=5,E16=6),1,0) -> 0 | AK28: =IF(OR(E16=4,E16=5,E16=6,E16=7,E16=8,E16=9,E16=10,E16="3A",E16="5A"),Q13,Q11) -> 0 | AS28: =-AT11*AT12 -> 0 | AT28: 0
AA29: rxe | AB29: =VLOOKUP(E$16,AA$4:AL$16,11,TRUE) -> 0 | AD29: =AD26 -> 2.5 | AE29: =-AE28 -> 0 | AF29: =IF(OR(E16="3A",E16="5A",E16=4,E16=5,E16=6),1,0) -> 0 | AI29: =0.4*AS8 -> 2 | AJ29: 0 | AS29: =AS28 -> 0 | AT29: =AT25 -> 6
AA30: rye | AB30: =VLOOKUP(E$16,AA$4:AL$16,12,TRUE) -> 0 | AI30: =0.6*AS8 -> 3 | AJ30: 0 | AS30: 0 | AT30: =AT29 -> 6
AD31: x | AE31: y | AK31: =IF(OR(E16=3,E16=5,E16=6,E16=9,E16="5A"),Q14,Q12) -> 1.997275 | AS31: 0 | AT31: =AT30+AT11*AT13 -> 6
AD32: 0 | AE32: 0 | AI32: =AS8 -> 5 | AJ32: =AJ23 -> 0 | AS32: =AS24 -> 5 | AT32: =AT31 -> 6
AD33: =AS8*AF33 -> 5 | AE33: 0 | AF33: =IF(OR(E16<7,E16="2A",E16="3A",E16="5A"),0,1) -> 1 | AI33: =AS8 -> 5 | AJ33: =AJ24 -> 0 | AS33: =AS32 -> 5 | AT33: =AT30 -> 6
AD34: 0 | AE34: =AT8 -> 6 | AK34: =IF(OR(E16="2A",E16="3A",E16="5A",E16=6),Q13,Q11) -> 0 | AS34: =AS33+AT14*AT11 -> 5 | AT34: =AT33 -> 6
AD35: =AD33 -> 5 | AE35: =AE34 -> 6 | AI35: =AI29 -> 2 | AJ35: =AT8 -> 6 | AS35: =AS34 -> 5 | AT35: 0
AD36: =AS8 -> 5 | AE36: 0 | AI36: =AI30 -> 3 | AJ36: =AJ35 -> 6 | AS36: =AS33 -> 5 | AT36: 0
AD37: =AS8 -> 5 | AE37: =AT8*AF37 -> 0 | AF37: =IF(E16=10,1,0) -> 0 | AS37: =AS36 -> 5 | AT37: =-AT15*AT11 -> 0
AS38: 0 | AT38: =AT37 -> 0
AS39: 0 | AT39: 0
AS40: -1 | AT40: -2
AS41: 6 | AT41: 8

Sheet L5
C3: L5 | AA3: Caso | AB3: kx | AC3: ky | AD3: wc | AE3: mx | AF3: my | AG3: mxe | AH3: mye | AI3: rx | AJ3: ry | AK3: rxe | AL3: rye
I4: Cargas | M4: Rigidez | P4: Momentos Fletores | AA4: 1 | AB4: =AB18^4/(1+AB18^4) -> 0.82073919 | AC4: =1-AB4 -> 0.17926081 | AD4: =5*AB4/384 -> 0.010686708 | AE4: =AB4/8 -> 0.1025924 | AF4: =AC4*AB18^2/8 -> 0.047946319 | AG4: 0 | AH4: 0 | AI4: =AC4*AB18/2 -> 0.13110985 | AJ4: =AB4/2 -> 0.4103696 | AK4: 0 | AL4: 0
I5: fd,ser | J5: =E11+E13*E12 -> 4.6 | M5: αi | N5: =MIN(0.8+0.2*E19/80,1) -> 0.8625 | P5: Mdx | Q5: =AB23*J6*E7^2 -> 1.2211198 | AA5: 2 | AB5: =5*AB18^4/(2+5*AB18^4) -> 0.91965394 | AC5: =1-AB5 -> 0.080346064 | AD5: =2*AB5/384 -> 0.0047898643 | AE5: =AB5/14.22 -> 0.064673273 | AF5: =AC5*AB18^2/8 -> 0.021489907 | AG5: =-AB5/8 -> -0.11495674 | AH5: 0 | AI5: =AC5*AB18/2 -> 0.058764435 | AJ5: =3*AB5/8 -> 0.34487023 | AK5: 0 | AL5: =5*AB5/8 -> 0.57478371
D6: Vãos | I6: fd | J6: =(E12+E11)*IF(E16=10,1.4*MAX(1.95-0.05*E23*100,1),1.4) -> 7.91 | M6: Eci | N6: =E20*5600*E19^0.5 -> 33600 | P6: Mdy | Q6: =AB24*J6*E7^2 -> 0.40575883 | AA6: 2A | AB6: =5*AB18^-4/(2+5*AB18^-4) -> 0.35318396 | AC6: =1-AB6 -> 0.64681604 | AD6: =2*AB6/384*AB18^4 -> 0.0084220839 | AE6: =AC6*AB18^2/8/AB18^2 -> 0.080852005 | AF6: =AB6/14.22*AB18^2 -> 0.053144862 | AG6: 0 | AH6: =-AB6/8*AB18^2 -> -0.094464992 | AI6: =3*AB6/8*AB18 -> 0.19373683 | AJ6: =AC6*AB18/2/AB18 -> 0.32340802 | AK6: =5*AB6/8*AB18 -> 0.32289472 | AL6: 0 | BC6: aa | BD6: bb | BE6: cc
D7: lx | E7: =VLOOKUP(C3,Resumo!B9:N28,5,FALSE) -> 1.545 | M7: Ecs | N7: =N6*N5 -> 28980 | P7: Mdxe | Q7: =(AB25*J6*E7^2-IF(E16=10,MAX(1.95-0.05*E23*100,1)*(1.4*J12*J13+1.4*J11*E7),0)) -> -2.1705405 | AA7: 3 | AB7: =5*AB18^4/(1+5*AB18^4) -> 0.95814555 | AC7: =1-AB7 -> 0.041854452 | AD7: =AB7/384 -> 0.0024951707 | AE7: =AB7/24 -> 0.039922731 | AF7: =AC7*AB18^2/8 -> 0.011194677 | AG7: =-AB7/12 -> -0.079845462 | AH7: 0 | AI7: =AC7*AB18/2 -> 0.030611994 | AJ7: 0 | AK7: 0 | AL7: =AB7/2 -> 0.47907277 | AS7: lx | AT7: ly | BB7: 0 | BC7: 0 | BD7: 0 | BE7: 0
D8: ly | E8: =VLOOKUP(C3,Resumo!B9:N28,9,FALSE) -> 2.26 | M8: D | N8: =N7*10^6*E23^3/(12*(1-0.2^2))/1000 -> 4347 | P8: Mdye | Q8: =AB26*J6*E7^2 -> 0 | AA8: 3A | AB8: =5*AB18^-4/(1+5*AB18^-4) -> 0.52200435 | AC8: =1-AB8 -> 0.47799565 | AD8: =AB8/384*AB18^4 -> 0.0062239017 | AE8: =AC8*AB18^2/8/AB18^2 -> 0.059749456 | AF8: =AB8/24*AB18^2 -> 0.046539616 | AG8: 0 | AH8: =-AB8/12*AB18^2 -> -0.093079232 | AI8: 0 | AJ8: =AC8*AB18/2/AB18 -> 0.23899782 | AK8: =AB8/2*AB18 -> 0.38178959 | AL8: 0 | AS8: 5 | AT8: 6 | BB8: =BA10 -> 71.428571 | BC8: 0 | BD8: 0 | BE8: 0
AA9: 4 | AB9: =AB18^4/(1+AB18^4) -> 0.82073919 | AC9: =1-AB9 -> 0.17926081 | AD9: =2*AB9/384 -> 0.0042746833 | AE9: =AB9/14.22 -> 0.057717243 | AF9: =AC9*AB18^2/14.22 -> 0.026974019 | AG9: =-AB9/8 -> -0.1025924 | AH9: =-AC9*AB18^2/8 -> -0.047946319 | AI9: =3*AC9*AB18/8 -> 0.098332385 | AJ9: =3*AB9/8 -> 0.3077772 | AK9: =5*AC9*AB18/8 -> 0.16388731 | AL9: =5*AB9/8 -> 0.51296199 | BB9: =BA10 -> 71.428571 | BC9: 0 | BD9: 0 | BE9: =AT8 -> 6
D10: Carga | I10: Laje em Balanço | M10: Flecha | P10: Reações de Apoio | AA10: 5 | AB10: =2*AB18^4/(1+2*AB18^4) -> 0.90154504 | AC10: =1-AB10 -> 0.098454962 | AD10: =AB10/384 -> 0.0023477735 | AE10: =AB10/24 -> 0.037564377 | AF10: =AC10*AB18^2/14.22 -> 0.014814873 | AG10: =-AB10/12 -> -0.075128753 | AH10: =-AC10*AB18^2/8 -> -0.026333436 | AI10: =3*AC10*AB18/8 -> 0.054006848 | AJ10: 0 | AK10: =5*AC10*AB18/8 -> 0.090011414 | AL10: =AB10/2 -> 0.45077252 | AY10: =-AT11*AT12 -> -0.5 | BA10: =1000*(AY10-AY$15)/(AY$16-AY$15) -> 71.428571 | BB10: =BA11 -> 142.85714 | BC10: 0 | BD10: 0 | BE10: =BE9 -> 6
D11: gk | E11: =VLOOKUP(C3,Resumo!B9:N28,10,FALSE) -> 4.15 | I11: Pvk | J11: 2.5 | M11: W0 | N11: =AB22*J5*E7^4/N8*1000+IF(E16=10,J11*E7^3/(3*N8)*1000,0) -> 0.028880542 | P11: Rdx | Q11: =AB27*J6*E7 -> 0.71815722 | AA11: 5A | AB11: =2*AB18^-4/(1+2*AB18^-4) -> 0.30402233 | AC11: =1-AB11 -> 0.69597767 | AD11: =AB11/384*AB18^4 -> 0.0036248837 | AE11: =AC11*AB18^2/14.22/AB18^2 -> 0.048943577 | AF11: =AB11/24*AB18^2 -> 0.027105296 | AG11: =-AC11*AB18^2/8/AB18^2 -> -0.086997209 | AH11: =-AB11/12*AB18^2 -> -0.054210591 | AI11: 0 | AJ11: =3*AC11*AB18/8/AB18 -> 0.26099163 | AK11: =AB11/2*AB18 -> 0.22235937 | AL11: =5*AC11*AB18/8/AB18 -> 0.43498604 | AS11: eng | AT11: =MIN(AS8:AT8)/10 -> 0.5 | AY11: 0 | BA11: =1000*(AY11-AY$15)/(AY$16-AY$15) -> 142.85714 | BB11: =BA11 -> 142.85714 | BC11: =-AT15*AT11 -> 0 | BD11: =AT8-BC11 -> 6 | BE11: =AT13*AT11 -> 0
D12: qk | E12: =VLOOKUP(C3,Resumo!B9:N28,11,FALSE) -> 1.5 | I12: Phk | J12: 1 | M12: W∞ | N12: =N11*(1+E26) -> 0.1010819 | P12: Rdy | Q12: =AB28*J6*E7 -> 4.2146418 | AA12: 6 | AB12: =AB18^4/(1+AB18^4) -> 0.82073919 | AC12: =1-AB12 -> 0.17926081 | AD12: =AB12/384 -> 0.0021373416 | AE12: =AB12/24 -> 0.034197466 | AF12: =AC12*AB18^2/24 -> 0.015982106 | AG12: =-AB12/12 -> -0.068394933 | AH12: =-AC12*AB18^2/12 -> -0.031964213 | AI12: 0 | AJ12: 0 | AK12: =AC12*AB18/2 -> 0.13110985 | AL12: =AB12/2 -> 0.4103696 | AS12: a | AT12: =IF(OR(E16=1,E16=7,E16="2A",E16="3A",E16="5A"),0,1) -> 1 | AY12: =AS8 -> 5 | BA12: =1000*(AY12-AY$15)/(AY$16-AY$15) -> 857.14286 | BB12: =BA12 -> 857.14286 | BC12: =BC11 -> 0 | BD12: =BD11 -> 6 | BE12: =BE11 -> 0
D13: ψ2 | E13: 0.3 | I13: H | J13: 1.2 | M13: Wadm | N13: =IF(E16=10,E7*1000/125,MIN(E7:E8)/250*1000) -> 6.18 | P13: Rdxe | Q13: =AB29*J6*E7 -> 0 | AA13: 7 | AB13: 0 | AC13: 0 | AD13: =5/384 -> 0.013020833 | AE13: =1/8 -> 0.125 | AF13: 0 | AG13: 0 | AH13: 0 | AI13: 0 | AJ13: =1/2 -> 0.5 | AK13: 0 | AL13: 0 | AS13: b | AT13: =IF(OR(E16="2A",E16="3A",E16="5A",E16=6),1,0) -> 0 | AY13: =AS8+AT11*AT14 -> 5 | BA13: =1000*(AY13-AY$15)/(AY$16-AY$15) -> 857.14286 | BB13: =BA12 -> 857.14286 | BC13: 0 | BD13: 0 | BE13: =AT8 -> 6
M14: =IF(N13>=N12,"Ok!","Aumentar h!!!") -> Ok! | P14: Rdye | Q14: =AB30*J6*E7 -> 7.024403 | AA14: 8 | AB14: 0 | AC14: 0 | AD14: =2/384 -> 0.0052083333 | AE14: =1/14.22 -> 0.070323488 | AF14: 0 | AG14: =-1/8 -> -0.125 | AH14: 0 | AI14: 0 | AJ14: =3/8 -> 0.375 | AK14: 0 | AL14: =5/8 -> 0.625 | AS14: c | AT14: =IF(OR(E16=1,E16=2,E16="2A",E16="3A",E16=4,E16=7,E16=8,E16=10),0,1) -> 0 | BB14: =BA13 -> 857.14286 | BC14: 0 | BD14: 0 | BE14: =AT8 -> 6
D15: Vinculação | AA15: 9 | AB15: 0 | AC15: 0 | AD15: =1/384 -> 0.0026041667 | AE15: =1/24 -> 0.041666667 | AF15: 0 | AG15: =-1/12 -> -0.083333333 | AH15: 0 | AI15: 0 | AJ15: 0 | AK15: 0 | AL15: =1/2 -> 0.5 | AS15: d | AT15: =IF(OR(E16="3A",E16="5A",E16=4,E16=5,E16=6),1,0) -> 0 | AY15: =AS40 -> -1 | AZ15: min | BB15: =BA13 -> 857.14286 | BC15: 0 | BD15: 0 | BE15: 0
D16: Caso | E16: =VLOOKUP(C3,Resumo!B9:N28,13,FALSE) -> 2 | AA16: 10 | AB16: 0 | AC16: 0 | AD16: =48/384 -> 0.125 | AE16: 0 | AF16: 0 | AG16: =-1/2 -> -0.5 | AH16: 0 | AI16: 0 | AJ16: 0 | AK16: 0 | AL16: 1 | AY16: =AS41 -> 6 | AZ16: max | BB16: 1000 | BC16: 0 | BD16: 0 | BE16: 0
D18: Concreto | AA18: λ | AB18: =E8/E7 -> 1.4627832 | AD18: x | AE18: y | AF18: =IF(AF19=0,"",Q7) | AG18: 0.8 | AI18: x | AJ18: y | AK18: =IF(E16=10,"",Q5) -> 1.2211198 | AL18: 0.8
D19: fck | E19: 25 | AD19: =(AS8-(1-AG18)/2*AS8)*AF19 -> 0 | AE19: =AT8/2 -> 3 | AF19: =IF(OR(E16=3,E16=5,E16="5A",E16=6,E16=9),1,0) -> 0 | AI19: =(AS8/2-(1-AL18)/2*AS8)*AK19 -> 2 | AJ19: =AT8/2 -> 3 | AK19: =IF(E16=10,0,1) -> 1
D20: αe | E20: 1.2 | AA20: kx | AB20: =VLOOKUP(E$16,AA$4:AL$16,2,TRUE) -> 0.91965394 | AD20: =((AS8-AD19)+AS8)*AF20 -> 0 | AE20: =AE19 -> 3 | AF20: =IF(OR(E16=3,E16=5,E16="5A",E16=6,E16=9),1,0) -> 0 | AI20: =((AS8/2-AI19)+AS8/2)*AK20 -> 3 | AJ20: =AJ19 -> 3 | AK20: =AK19 -> 1
AA21: ky | AB21: =VLOOKUP(E$16,AA$4:AL$16,3,TRUE) -> 0.080346064 | AF21: =IF(AF22=0,"",Q7) -> -2.1705405 | AS21: x | AT21: y
D22: Espessura | AA22: wc | AB22: =VLOOKUP(E$16,AA$4:AL$16,4,TRUE) -> 0.0047898643 | AD22: =-(1-AG18)/2*AS8*AF22 -> -0.5 | AE22: =AE19 -> 3 | AF22: =IF(OR(E16=1,E16="2A",E16="3A",E16="5A",E16=7),0,1) -> 1 | AI22: x | AJ22: y | AK22: =IF(OR(E16=7,E16=8,E16=9,E16=10),"",Q6) -> 0.40575883 | AL22: 0.8 | AS22: 0 | AT22: 0
D23: h | E23: 0.12 | AA23: mx | AB23: =VLOOKUP(E$16,AA$4:AL$16,5,TRUE) -> 0.064673273 | AD23: =-AD22 -> 0.5 | AE23: =AE20 -> 3 | AF23: =IF(OR(E16=1,E16="2A",E16="3A",E16="5A",E16=7),0,1) -> 1 | AI23: =AS8/2 -> 2.5 | AJ23: =(AT8/2-(1-AL22)/2*AT8)*AK23 -> 2.4 | AK23: =IF(OR(E16=7,E16=8,E16=9,E16=10),0,1) -> 1 | AS23: =AS8 -> 5 | AT23: 0
AA24: my | AB24: =VLOOKUP(E$16,AA$4:AL$16,6,TRUE) -> 0.021489907 | AF24: =IF(AF26=0,"",Q8) | AG24: 0.8 | AI24: =AI23 -> 2.5 | AJ24: =((AT8/2-AJ23)+AT8/2)*AK23 -> 3.6 | AS24: =AS8 -> 5 | AT24: =AT8 -> 6
D25: Fluência | AA25: mxe | AB25: =VLOOKUP(E$16,AA$4:AL$16,7,TRUE) -> -0.11495674 | AD25: =AS8/2 -> 2.5 | AE25: =(AT8+(1-AG24)/2*AT8)*AF25 -> 0 | AF25: =IF(OR(E16=6,E16="2A",E16="3A",E16="5A"),1,0) -> 0 | AK25: =IF(OR(E16=1,E16=7,E16="2A",E16="3A",E16="5A"),Q12,Q14) -> 7.024403 | AS25: 0 | AT25: =AT24 -> 6
D26: φ | E26: 2.5 | AA26: mye | AB26: =VLOOKUP(E$16,AA$4:AL$16,8,TRUE) -> 0 | AD26: =AD25 -> 2.5 | AE26: =(AT8-(AE25-AT8))*AF26 -> 0 | AF26: =IF(OR(E16=6,E16="2A",E16="3A",E16="5A"),1,0) -> 0 | AI26: 0 | AJ26: =0.4*AT8 -> 2.4 | AS26: 0 | AT26: 0
AA27: rx | AB27: =VLOOKUP(E$16,AA$4:AL$16,9,TRUE) -> 0.058764435 | AF27: =IF(AF28=0,"",Q8) | AI27: 0 | AJ27: =0.6*AT8 -> 3.6 | AS27: 0 | AT27: 0
AA28: ry | AB28: =VLOOKUP(E$16,AA$4:AL$16,10,TRUE) -> 0.34487023 | AD28: =AD25 -> 2.5 | AE28: =(1-AG24)/2*AT8*AF28 -> 0 | AF28: =IF(OR(E16="3A",E16="5A",E16=4,E16=5,E16=6),1,0) -> 0 | AK28: =IF(OR(E16=4,E16=5,E16=6,E16=7,E16=8,E16=9,E16=10,E16="3A",E16="5A"),Q13,Q11) -> 0.71815722 | AS28: =-AT11*AT12 -> -0.5 | AT28: 0
AA29: rxe | AB29: =VLOOKUP(E$16,AA$4:AL$16,11,TRUE) -> 0 | AD29: =AD26 -> 2.5 | AE29: =-AE28 -> 0 | AF29: =IF(OR(E16="3A",E16="5A",E16=4,E16=5,E16=6),1,0) -> 0 | AI29: =0.4*AS8 -> 2 | AJ29: 0 | AS29: =AS28 -> -0.5 | AT29: =AT25 -> 6
AA30: rye | AB30: =VLOOKUP(E$16,AA$4:AL$16,12,TRUE) -> 0.57478371 | AI30: =0.6*AS8 -> 3 | AJ30: 0 | AS30: 0 | AT30: =AT29 -> 6
AD31: x | AE31: y | AK31: =IF(OR(E16=3,E16=5,E16=6,E16=9,E16="5A"),Q14,Q12) -> 4.2146418 | AS31: 0 | AT31: =AT30+AT11*AT13 -> 6
AD32: 0 | AE32: 0 | AI32: =AS8 -> 5 | AJ32: =AJ23 -> 2.4 | AS32: =AS24 -> 5 | AT32: =AT31 -> 6
AD33: =AS8*AF33 -> 0 | AE33: 0 | AF33: =IF(OR(E16<7,E16="2A",E16="3A",E16="5A"),0,1) -> 0 | AI33: =AS8 -> 5 | AJ33: =AJ24 -> 3.6 | AS33: =AS32 -> 5 | AT33: =AT30 -> 6
AD34: 0 | AE34: =AT8 -> 6 | AK34: =IF(OR(E16="2A",E16="3A",E16="5A",E16=6),Q13,Q11) -> 0.71815722 | AS34: =AS33+AT14*AT11 -> 5 | AT34: =AT33 -> 6
AD35: =AD33 -> 0 | AE35: =AE34 -> 6 | AI35: =AI29 -> 2 | AJ35: =AT8 -> 6 | AS35: =AS34 -> 5 | AT35: 0
AD36: =AS8 -> 5 | AE36: 0 | AI36: =AI30 -> 3 | AJ36: =AJ35 -> 6 | AS36: =AS33 -> 5 | AT36: 0
AD37: =AS8 -> 5 | AE37: =AT8*AF37 -> 0 | AF37: =IF(E16=10,1,0) -> 0 | AS37: =AS36 -> 5 | AT37: =-AT15*AT11 -> 0
AS38: 0 | AT38: =AT37 -> 0
AS39: 0 | AT39: 0
AS40: -1 | AT40: -2
AS41: 6 | AT41: 8

Sheet L6
C3: L6 | AA3: Caso | AB3: kx | AC3: ky | AD3: wc | AE3: mx | AF3: my | AG3: mxe | AH3: mye | AI3: rx | AJ3: ry | AK3: rxe | AL3: rye
I4: Cargas | M4: Rigidez | P4: Momentos Fletores | AA4: 1 | AB4: =AB18^4/(1+AB18^4) -> 0.63868965 | AC4: =1-AB4 -> 0.36131035 | AD4: =5*AB4/384 -> 0.0083162715 | AE4: =AB4/8 -> 0.079836206 | AF4: =AC4*AB18^2/8 -> 0.060047531 | AG4: 0 | AH4: 0 | AI4: =AC4*AB18/2 -> 0.20830648 | AJ4: =AB4/2 -> 0.31934482 | AK4: 0 | AL4: 0
I5: fd,ser | J5: =E11+E13*E12 -> 4.6 | M5: αi | N5: =MIN(0.8+0.2*E19/80,1) -> 0.8625 | P5: Mdx | Q5: =AB23*J6*E7^2 -> 1.7426035 | AA5: 2 | AB5: =5*AB18^4/(2+5*AB18^4) -> 0.81547294 | AC5: =1-AB5 -> 0.18452706 | AD5: =2*AB5/384 -> 0.0042472549 | AE5: =AB5/14.22 -> 0.057346901 | AF5: =AC5*AB18^2/8 -> 0.030667249 | AG5: =-AB5/8 -> -0.10193412 | AH5: 0 | AI5: =AC5*AB18/2 -> 0.1063855 | AJ5: =3*AB5/8 -> 0.30580235 | AK5: 0 | AL5: =5*AB5/8 -> 0.50967058
D6: Vãos | I6: fd | J6: =(E12+E11)*IF(E16=10,1.4*MAX(1.95-0.05*E23*100,1),1.4) -> 7.91 | M6: Eci | N6: =E20*5600*E19^0.5 -> 33600 | P6: Mdy | Q6: =AB24*J6*E7^2 -> 0.93188742 | AA6: 2A | AB6: =5*AB18^-4/(2+5*AB18^-4) -> 0.58579512 | AC6: =1-AB6 -> 0.41420488 | AD6: =2*AB6/384*AB18^4 -> 0.0053932927 | AE6: =AC6*AB18^2/8/AB18^2 -> 0.05177561 | AF6: =AB6/14.22*AB18^2 -> 0.054771028 | AG6: 0 | AH6: =-AB6/8*AB18^2 -> -0.097355501 | AI6: =3*AB6/8*AB18 -> 0.25329661 | AJ6: =AC6*AB18/2/AB18 -> 0.20710244 | AK6: =5*AB6/8*AB18 -> 0.42216102 | AL6: 0 | BC6: aa | BD6: bb | BE6: cc
D7: lx | E7: =VLOOKUP(C3,Resumo!B9:N28,5,FALSE) -> 1.96 | M7: Ecs | N7: =N6*N5 -> 28980 | P7: Mdxe | Q7: =(AB25*J6*E7^2-IF(E16=10,MAX(1.95-0.05*E23*100,1)*(1.4*J12*J13+1.4*J11*E7),0)) -> -3.0974777 | AA7: 3 | AB7: =5*AB18^4/(1+5*AB18^4) -> 0.89835868 | AC7: =1-AB7 -> 0.10164132 | AD7: =AB7/384 -> 0.0023394757 | AE7: =AB7/24 -> 0.037431612 | AF7: =AC7*AB18^2/8 -> 0.016892154 | AG7: =-AB7/12 -> -0.074863223 | AH7: 0 | AI7: =AC7*AB18/2 -> 0.058599332 | AJ7: 0 | AK7: 0 | AL7: =AB7/2 -> 0.44917934 | AS7: lx | AT7: ly | BB7: 0 | BC7: 0 | BD7: 0 | BE7: 0
D8: ly | E8: =VLOOKUP(C3,Resumo!B9:N28,9,FALSE) -> 2.26 | M8: D | N8: =N7*10^6*E23^3/(12*(1-0.2^2))/1000 -> 4347 | P8: Mdye | Q8: =AB26*J6*E7^2 -> 0 | AA8: 3A | AB8: =5*AB18^-4/(1+5*AB18^-4) -> 0.73880303 | AC8: =1-AB8 -> 0.26119697 | AD8: =AB8/384*AB18^4 -> 0.0034010022 | AE8: =AC8*AB18^2/8/AB18^2 -> 0.032649621 | AF8: =AB8/24*AB18^2 -> 0.040928154 | AG8: 0 | AH8: =-AB8/12*AB18^2 -> -0.081856309 | AI8: 0 | AJ8: =AC8*AB18/2/AB18 -> 0.13059849 | AK8: =AB8/2*AB18 -> 0.42594256 | AL8: 0 | AS8: 5 | AT8: 6 | BB8: =BA10 -> 71.428571 | BC8: 0 | BD8: 0 | BE8: 0
AA9: 4 | AB9: =AB18^4/(1+AB18^4) -> 0.63868965 | AC9: =1-AB9 -> 0.36131035 | AD9: =2*AB9/384 -> 0.0033265086 | AE9: =AB9/14.22 -> 0.044914884 | AF9: =AC9*AB18^2/14.22 -> 0.033782015 | AG9: =-AB9/8 -> -0.079836206 | AH9: =-AC9*AB18^2/8 -> -0.060047531 | AI9: =3*AC9*AB18/8 -> 0.15622986 | AJ9: =3*AB9/8 -> 0.23950862 | AK9: =5*AC9*AB18/8 -> 0.2603831 | AL9: =5*AB9/8 -> 0.39918103 | BB9: =BA10 -> 71.428571 | BC9: 0 | BD9: 0 | BE9: =AT8 -> 6
D10: Carga | I10: Laje em Balanço | M10: Flecha | P10: Reações de Apoio | AA10: 5 | AB10: =2*AB18^4/(1+2*AB18^4) -> 0.77951264 | AC10: =1-AB10 -> 0.22048736 | AD10: =AB10/384 -> 0.0020299808 | AE10: =AB10/24 -> 0.032479693 | AF10: =AC10*AB18^2/14.22 -> 0.020615261 | AG10: =-AB10/12 -> -0.064959387 | AH10: =-AC10*AB18^2/8 -> -0.036643626 | AI10: =3*AC10*AB18/8 -> 0.095338284 | AJ10: 0 | AK10: =5*AC10*AB18/8 -> 0.15889714 | AL10: =AB10/2 -> 0.38975632 | AY10: =-AT11*AT12 -> -0.5 | BA10: =1000*(AY10-AY$15)/(AY$16-AY$15) -> 71.428571 | BB10: =BA11 -> 142.85714 | BC10: 0 | BD10: 0 | BE10: =BE9 -> 6
D11: gk | E11: =VLOOKUP(C3,Resumo!B9:N28,10,FALSE) -> 4.15 | I11: Pvk | J11: 2.5 | M11: W0 | N11: =AB22*J5*E7^4/N8*1000+IF(E16=10,J11*E7^3/(3*N8)*1000,0) -> 0.066328595 | P11: Rdx | Q11: =AB27*J6*E7 -> 1.6493583 | AA11: 5A | AB11: =2*AB18^-4/(1+2*AB18^-4) -> 0.5308273 | AC11: =1-AB11 -> 0.4691727 | AD11: =AB11/384*AB18^4 -> 0.0024436078 | AE11: =AC11*AB18^2/14.22/AB18^2 -> 0.03299386 | AF11: =AB11/24*AB18^2 -> 0.029406731 | AG11: =-AC11*AB18^2/8/AB18^2 -> -0.058646587 | AH11: =-AB11/12*AB18^2 -> -0.058813462 | AI11: 0 | AJ11: =3*AC11*AB18/8/AB18 -> 0.17593976 | AK11: =AB11/2*AB18 -> 0.30603819 | AL11: =5*AC11*AB18/8/AB18 -> 0.29323293 | AS11: eng | AT11: =MIN(AS8:AT8)/10 -> 0.5 | AY11: 0 | BA11: =1000*(AY11-AY$15)/(AY$16-AY$15) -> 142.85714 | BB11: =BA11 -> 142.85714 | BC11: =-AT15*AT11 -> 0 | BD11: =AT8-BC11 -> 6 | BE11: =AT13*AT11 -> 0
D12: qk | E12: =VLOOKUP(C3,Resumo!B9:N28,11,FALSE) -> 1.5 | I12: Phk | J12: 1 | M12: W∞ | N12: =N11*(1+E26) -> 0.23215008 | P12: Rdy | Q12: =AB28*J6*E7 -> 4.7410373 | AA12: 6 | AB12: =AB18^4/(1+AB18^4) -> 0.63868965 | AC12: =1-AB12 -> 0.36131035 | AD12: =AB12/384 -> 0.0016632543 | AE12: =AB12/24 -> 0.026612069 | AF12: =AC12*AB18^2/24 -> 0.020015844 | AG12: =-AB12/12 -> -0.053224137 | AH12: =-AC12*AB18^2/12 -> -0.040031687 | AI12: 0 | AJ12: 0 | AK12: =AC12*AB18/2 -> 0.20830648 | AL12: =AB12/2 -> 0.31934482 | AS12: a | AT12: =IF(OR(E16=1,E16=7,E16="2A",E16="3A",E16="5A"),0,1) -> 1 | AY12: =AS8 -> 5 | BA12: =1000*(AY12-AY$15)/(AY$16-AY$15) -> 857.14286 | BB12: =BA12 -> 857.14286 | BC12: =BC11 -> 0 | BD12: =BD11 -> 6 | BE12: =BE11 -> 0
D13: ψ2 | E13: 0.3 | I13: H | J13: 1.2 | M13: Wadm | N13: =IF(E16=10,E7*1000/125,MIN(E7:E8)/250*1000) -> 7.84 | P13: Rdxe | Q13: =AB29*J6*E7 -> 0 | AA13: 7 | AB13: 0 | AC13: 0 | AD13: =5/384 -> 0.013020833 | AE13: =1/8 -> 0.125 | AF13: 0 | AG13: 0 | AH13: 0 | AI13: 0 | AJ13: =1/2 -> 0.5 | AK13: 0 | AL13: 0 | AS13: b | AT13: =IF(OR(E16="2A",E16="3A",E16="5A",E16=6),1,0) -> 0 | AY13: =AS8+AT11*AT14 -> 5 | BA13: =1000*(AY13-AY$15)/(AY$16-AY$15) -> 857.14286 | BB13: =BA12 -> 857.14286 | BC13: 0 | BD13: 0 | BE13: =AT8 -> 6
M14: =IF(N13>=N12,"Ok!","Aumentar h!!!") -> Ok! | P14: Rdye | Q14: =AB30*J6*E7 -> 7.9017289 | AA14: 8 | AB14: 0 | AC14: 0 | AD14: =2/384 -> 0.0052083333 | AE14: =1/14.22 -> 0.070323488 | AF14: 0 | AG14: =-1/8 -> -0.125 | AH14: 0 | AI14: 0 | AJ14: =3/8 -> 0.375 | AK14: 0 | AL14: =5/8 -> 0.625 | AS14: c | AT14: =IF(OR(E16=1,E16=2,E16="2A",E16="3A",E16=4,E16=7,E16=8,E16=10),0,1) -> 0 | BB14: =BA13 -> 857.14286 | BC14: 0 | BD14: 0 | BE14: =AT8 -> 6
