Workbook

Sheet CONSIDERAÇÕES
A1: CONSIDERAÇÕES
A3: Base engastada no mínimo 4 chumbadores
A5: Nunca utilizar concredo simples (sem armação)
A7: As bases engastadas estão sujeitas à ação simultânea de : momento fleto e esforços normais e horizontais.
A9: Para casos de bsaes rotuladas, o sistema de travamento dos pilares deverá considerar a necessidade de utilizar contraventamento para estabilidade do conjunto
A11: A espessura da chapa de base pode ser reduzida com o uso de enrijecedores de coluna
A13: Deixar os furos da placa de base com 3,2mm a mais que o diâmetro da barra
A15: Assentar placa de base sobre grout e nunca diretamente sobre a fundação de concreto
A17: Fixar os chumbadores a uma altura de 300 a 500mm da base, proporcionando um ótimo engastamento

Sheet PLACAS DE BASE (2)
C3: DIMENSIONAMENTO DE PLACAS DE BASE
C4: SUBMETIDA A ESFORÇO DE COMPRESSÃO AXIAL COM MOMENTO
C5: MÉTODO AISC-ASD
C6: (PERFIS H ou W - ENGASTADAS)
C8: Aço:
C9: fy | D9: =AÇOS!C6 -> 34.5 | E9: kN/cm²
C10: fu | D10: =AÇOS!D6 -> 48.5 | E10: kN/cm²
C12: Cargas:
C13: NSdc | D13: 30.5 | E13: kN | F13: =D13*0.102 -> 3.111 | G13: tf
C14: HSd | D14: 18.89 | E14: kN | F14: =D14*0.102 -> 1.92678 | G14: tf
C15: MSd | D15: 39.54 | E15: kNm | F15: =D15*0.102 -> 4.03308 | G15: tfm
C17: Número de Chumbadores
C18: nt | D18: 3 | E18: *tração
C19: nc | D19: =D18 -> 3 | E19: *compressão
C21: Diâmetro dos Chumbadores (Tração)
C22: dchumb | D22: 19.05 | E22: mm
C23: dmín(furo-furo) | D23: =D22*6.5 -> 123.825 | E23: mm | F23: distância interna entre chumbadores
C24: d(furo-furo)(projeto) | D24: 135 | E24: mm | F24: distância interna entre chumbadores de projeto
C25: dmín(furo-borda) | D25: =D22*2 -> 38.1 | E25: mm | F25: distância entre chumbador e borda
C26: dborda(projeto) | D26: 40 | F26: distância entre chumbador e borda de projeto
C27: dconcreto | D27: =D26 -> 40 | E27: mm | F27: distância mínima entre a borda da chapa e o concreto
C28: dalavanca | D28: =D48-2*D26 -> 370 | E28: mm | F28: distância braço alavanca da linha de chumbadores
C29: NSdt; Chumbador | D29: =D15*100/(D28/10) -> 106.86486 | E29: kN | F29: Tração solicitante nos chumbadores
C30: NSdt/Barra | D30: =D29/D18 -> 35.621622 | E30: kN | F30: Tração solicitante nos chumbadores
C31: NSdc/Barra | D31: =D14/D18 -> 6.2966667 | E31: kN
C32: Abarra | D32: =PI()*(D22/10)^2/4 -> 2.8502296 | E32: cm²
C33: NRdt/Barra | D33: =0.33*D10*D32 -> 45.617924 | E33: kN | F33: Tração resistente de cada chumbador
C34: Verificação | D34: =D30/D33 -> 0.78086897 | E34: % | F34: % Utilização da barra à tração
C35: NRdc/Barra | D35: =0.33*D32*D9 -> 32.449864 | E35: kN
C36: Verificação | D36: =D31/D35 -> 0.19404293 | E36: % | F36: % Utilização da barra à cisalhamento
C38: Dimensões do Perfil
C39: Peril | D39: W 250 x 32
C40: bf | D40: 146 | E40: mm
C41: d | D41: 258 | E41: mm
C42: m | D42: =(D48-(0.95*D41))/2 -> 102.45 | E42: mm
C43: n | D43: =(D48-(0.8*D40))/2 -> 166.6 | E43: mm
C44: n' | D44: =SQRT(D41*D40)/4 -> 48.520614 | E44: mm
C46: Placa de Base
C47: B | D47: 350 | E47: mm
C48: C | D48: 450 | E48: mm
...

Sheet PLACAS DE BASE
C3: DIMENSIONAMENTO DE PLACAS DE BASE
C4: SUBMETIDA A ESFORÇO DE COMPRESSÃO AXIAL COM MOMENTO
C5: MÉTODO AISC-ASD
C6: (PERFIS H ou W - ENGASTADAS)
C8: Aço:
C9: fy | D9: =AÇOS!C6 -> 34.5 | E9: kN/cm²
C10: fu | D10: =AÇOS!D6 -> 48.5 | E10: kN/cm²
C12: Cargas:
C13: NSdc | D13: 900 | E13: kN | F13: =D13*0.102 -> 91.8 | G13: tf
C14: HSd | D14: 48.6 | E14: kN | F14: =D14*0.102 -> 4.9572 | G14: tf
C15: MSd | D15: 45 | E15: kNm | F15: =D15*0.102 -> 4.59 | G15: tfm
C17: Número de Chumbadores
C18: nt | D18: 3 | E18: *tração
C19: nc | D19: =D18 -> 3 | E19: *compressão
C21: Diâmetro dos Chumbadores (Tração)
C22: dchumb | D22: 22.23 | E22: mm
C23: dmín(furo-furo) | D23: =D22*6.5 -> 144.495 | E23: mm | F23: distância interna entre chumbadores
C24: d(furo-furo)(projeto) | D24: 150 | E24: mm | F24: distância interna entre chumbadores de projeto
C25: dmín(furo-borda) | D25: =D22*2 -> 44.46 | E25: mm | F25: distância entre chumbador e borda
C26: dborda(projeto) | D26: 50 | F26: distância entre chumbador e borda de projeto
C27: dconcreto | D27: =D26 -> 50 | E27: mm | F27: distância mínima entre a borda da chapa e o concreto
C28: dalavanca | D28: =D48-2*D26 -> 322 | E28: mm | F28: distância braço alavanca da linha de chumbadores
C29: NSdt; Chumbador | D29: =D15*100/(D28/10) -> 139.75155 | E29: kN | F29: Tração solicitante nos chumbadores
C30: NSdt/Barra | D30: =D29/D18 -> 46.583851 | E30: kN | F30: Tração solicitante nos chumbadores
C31: NSdc/Barra | D31: =D14/D18 -> 16.2 | E31: kN
C32: Abarra | D32: =PI()*(D22/10)^2/4 -> 3.8812249 | E32: cm²
C33: NRdt/Barra | D33: =0.33*D10*D32 -> 62.119004 | E33: kN | F33: Tração resistente de cada chumbador
C34: Verificação | D34: =D30/D33 -> 0.74991303 | E34: % | F34: % Utilização da barra à tração
C35: NRdc/Barra | D35: =0.33*D32*D9 -> 44.187745 | E35: kN
C36: Verificação | D36: =D31/D35 -> 0.36661748 | E36: % | F36: % Utilização da barra à cisalhamento
C38: Dimensões do Perfil
C39: Peril | D39: W 200 x 86 (HP)
C40: bf | D40: 209 | E40: mm
C41: d | D41: 222 | E41: mm
C42: m | D42: =(D48-(0.95*D41))/2 -> 105.55 | E42: mm
C43: n | D43: =(D48-(0.8*D40))/2 -> 127.4 | E43: mm
C44: n' | D44: =SQRT(D41*D40)/4 -> 53.850487 | E44: mm
C46: Placa de Base
C47: B | D47: 400 | E47: mm
C48: C | D48: 422 | E48: mm
...

Sheet PLACAS DE BASE - COMPRESSÃO
C3: DIMENSIONAMENTO DE PLACAS DE BASE
C4: SUBMETIDA A ESFORÇO DE COMPRESSÃO AXIAL
C5: MÉTODO AISC-ASD
C6: (PERFIS H ou W - ENGASTADAS)
C8: Aço:
C9: fy | D9: =AÇOS!C6 -> 34.5 | E9: kN/cm²
C10: fu | D10: =AÇOS!D6 -> 48.5 | E10: kN/cm²
C12: Cargas:
C13: NSdc | D13: 900 | E13: kN | F13: =D13*0.102 -> 91.8 | G13: tf
C14: HSd | D14: 48.6 | E14: kN | F14: =D14*0.102 -> 4.9572 | G14: tf
C15: MSd | D15: 45 | E15: kNm | F15: =D15*0.102 -> 4.59 | G15: tfm
C17: Número de Chumbadores
C18: nt | D18: 2 | E18: *tração
C19: nc | D19: =D18 -> 2 | E19: *compressão
C21: Diâmetro dos Chumbadores
C22: dchumb | D22: 25.4 | E22: mm
C23: dinterna | D23: =D22*6.5 -> 165.1 | E23: mm | F23: distância interna entre chumbadores
C24: dint,projeto | D24: 150 | E24: mm | F24: distância interna entre chumbadores de projeto
C25: dborda,projeto | D25: =D22*2 -> 50.8 | E25: mm | F25: distância entre chumbador e borda
C26: dborda | D26: 50 | F26: distância entre chumbador e borda de projeto
C27: dconcreto | D27: =D26 -> 50 | E27: mm | F27: distância mínima entre a borda da chapa e o concreto
C28: dalavanca | D28: =D45-2*D26 -> 322 | E28: mm | F28: distância braço alavanca da linha de chumbadores
C29: NSdt | D29: =D15*100/(D28/10) -> 139.75155 | E29: kN | F29: Tração solicitante nos chumbadores
C30: NSdt/Barra | D30: =D29/D18 -> 69.875776 | E30: kN | F30: Tração solicitante nos chumbadores
C31: Abarra | D31: =PI()*(D22/10)^2/4 -> 5.0670748 | E31: cm²
C32: NRdt/Barra | D32: =0.33*D10*D31 -> 81.098532 | E32: kN | F32: Tração resistente de cada chumbador
C33: Verificação | D33: =D30/D32 -> 0.8616158 | E33: % | F33: % Utilização da barra
C35: Dimensões do Perfil
C36: Peril | D36: W 200 x 86 (HP)
C37: bf | D37: 209 | E37: mm
C38: d | D38: 222 | E38: mm
C39: m | D39: =(D45-(0.95*D38))/2 -> 105.55 | E39: mm
C40: n | D40: =(D45-(0.8*D37))/2 -> 127.4 | E40: mm
C41: n' | D41: =SQRT(D38*D37)/4 -> 53.850487 | E41: mm
C43: Placa de Base
C44: B | D44: 400 | E44: mm
C45: C | D45: 422 | E45: mm
C46: fc
C47: M
C48: fc | D48: =D13/((D44/10)*(D45/10)) -> 0.53317536 | E48: kN/cm²
...

Sheet DISTÂNCIA ENTRE FUROS
B2: Diâmetro db | C2: Diâmetro do furo padrão | D2: Distância entre centro à centro de furos padrão | E2: Distância entre centro à borda de furos padrão
D3: s | E3: e
B4: mm | C4: mm | D4: mm | E4: mm
B5: 5 | C5: =B5+1.5 -> 6.5 | D5: =3*B5 -> 15 | E5: =1.75*B5 -> 8.75
B6: 6 | C6: =B6+1.5 -> 7.5 | D6: =3*B6 -> 18 | E6: =1.75*B6 -> 10.5
B7: 8 | C7: =B7+1.5 -> 9.5 | D7: =3*B7 -> 24 | E7: =1.75*B7 -> 14
B8: 10 | C8: =B8+1.5 -> 11.5 | D8: =3*B8 -> 30 | E8: =1.75*B8 -> 17.5
B9: 12 | C9: =B9+1.5 -> 13.5 | D9: =3*B9 -> 36 | E9: =1.75*B9 -> 21
B10: 16 | C10: =B10+1.5 -> 17.5 | D10: =3*B10 -> 48 | E10: =1.75*B10 -> 28
B11: 20 | C11: =B11+1.5 -> 21.5 | D11: =3*B11 -> 60 | E11: =1.75*B11 -> 35
B12: 22 | C12: =B12+1.5 -> 23.5 | D12: =3*B12 -> 66 | E12: =1.75*B12 -> 38.5
B13: 24 | C13: =B13+1.5 -> 25.5 | D13: =3*B13 -> 72 | E13: =1.75*B13 -> 42
B14: 27 | C14: =B14+1.5 -> 28.5 | D14: =3*B14 -> 81 | E14: =1.75*B14 -> 47.25
B15: 30 | C15: =B15+1.5 -> 31.5 | D15: =3*B15 -> 90 | E15: =1.75*B15 -> 52.5
B16: Fonte: Tabela 14 da NBR 8800
B18: Para qualquer borda de uma parte ligada, a distância do centro do parafuso, ou da barra redonda rosqueada, mais próximo até essa borda não pode exceder a 12 vezes a espessura da parte ligada considerada, nem 150 mm.

Sheet DIÂMETROS
A1: Cisalhamento: (AISC-ASD) | F1: Cisalhamento: (AISC-LRFD)
A2: MIN | B2: MAX | C2: SELEÇÃO | D2: DIÂMETRO | F2: MIN | G2: MAX | H2: SELEÇÃO | I2: POTÊNCIA
A3: 0 | B3: 4.76 | C3: 1 | D3: 4.76 | F3: 0 | G3: 4.76 | H3: 1 | I3: 4.76
A4: =B3 -> 4.76 | B4: 6.35 | C4: 2 | D4: 6.35 | F4: =G3 -> 4.76 | G4: 6.35 | H4: 2 | I4: 6.35
A5: =B4 -> 6.35 | B5: 7.94 | C5: 3 | D5: 7.94 | F5: =G4 -> 6.35 | G5: 7.94 | H5: 3 | I5: 7.94
A6: =B5 -> 7.94 | B6: 9.53 | C6: 4 | D6: 9.53 | F6: =G5 -> 7.94 | G6: 9.53 | H6: 4 | I6: 9.53
A7: =B6 -> 9.53 | B7: 12.7 | C7: 5 | D7: 12.7 | F7: =G6 -> 9.53 | G7: 12.7 | H7: 5 | I7: 12.7
A8: =B7 -> 12.7 | B8: 15.88 | C8: 6 | D8: 15.88 | F8: =G7 -> 12.7 | G8: 15.88 | H8: 6 | I8: 15.88
A9: =B8 -> 15.88 | B9: 19.05 | C9: 7 | D9: 19.05 | F9: =G8 -> 15.88 | G9: 19.05 | H9: 7 | I9: 19.05
A10: =B9 -> 19.05 | B10: 22.23 | C10: 8 | D10: 22.23 | F10: =G9 -> 19.05 | G10: 22.23 | H10: 8 | I10: 22.23
A11: =B10 -> 22.23 | B11: 25.4 | C11: 9 | D11: 25.4 | F11: =G10 -> 22.23 | G11: 25.4 | H11: 9 | I11: 25.4
A12: =B11 -> 25.4 | B12: 31.75 | C12: 10 | D12: 31.75 | F12: =G11 -> 25.4 | G12: 31.75 | H12: 10 | I12: 31.75
A13: =B12 -> 31.75 | B13: 44.44 | C13: 11 | D13: 44.44 | F13: =G12 -> 31.75 | G13: 44.44 | H13: 11 | I13: 44.44
A14: =B13 -> 44.44 | B14: 50.8 | C14: 12 | D14: 50.8 | F14: =G13 -> 44.44 | G14: 50.8 | H14: 12 | I14: 50.8
A15: =B14 -> 50.8 | B15: 63.5 | C15: 13 | D15: 63.5 | F15: =G14 -> 50.8 | G15: 63.5 | H15: 13 | I15: 63.5
C16: RESULTADO | D16: RESULTADO | H16: RESULTADO | I16: RESULTADO
C17: =SQRT(4*('PLACAS DE BASE - COMPRESSÃO'!D31*100)/PI()) -> 25.4 | D17: =VLOOKUP(C17,A3:D15,4) -> 31.75 | H17: =VLOOKUP(#REF!,F3:H15,3) -> #REF! | I17: =VLOOKUP(H17,H3:I15,2) -> #REF!
A19: Tração: (AISC-ASD) | F19: Tração: (AISC-LRFD)
A20: MIN | B20: MAX | C20: SELEÇÃO | D20: POTÊNCIA | F20: MIN | G20: MAX | H20: SELEÇÃO | I20: POTÊNCIA
A21: 0 | B21: 4.76 | C21: 1 | D21: 4.76 | F21: 0 | G21: 4.76 | H21: 1 | I21: 4.76
A22: =B21 -> 4.76 | B22: 6.35 | C22: 2 | D22: 6.35 | F22: =G21 -> 4.76 | G22: 6.35 | H22: 2 | I22: 6.35
A23: =B22 -> 6.35 | B23: 7.94 | C23: 3 | D23: 7.94 | F23: =G22 -> 6.35 | G23: 7.94 | H23: 3 | I23: 7.94
A24: =B23 -> 7.94 | B24: 9.53 | C24: 4 | D24: 9.53 | F24: =G23 -> 7.94 | G24: 9.53 | H24: 4 | I24: 9.53
A25: =B24 -> 9.53 | B25: 12.7 | C25: 5 | D25: 12.7 | F25: =G24 -> 9.53 | G25: 12.7 | H25: 5 | I25: 12.7
A26: =B25 -> 12.7 | B26: 15.88 | C26: 6 | D26: 15.88 | F26: =G25 -> 12.7 | G26: 15.88 | H26: 6 | I26: 15.88
A27: =B26 -> 15.88 | B27: 19.05 | C27: 7 | D27: 19.05 | F27: =G26 -> 15.88 | G27: 19.05 | H27: 7 | I27: 19.05
A28: =B27 -> 19.05 | B28: 22.23 | C28: 8 | D28: 22.23 | F28: =G27 -> 19.05 | G28: 22.23 | H28: 8 | I28: 22.23
A29: =B28 -> 22.23 | B29: 25.4 | C29: 9 | D29: 25.4 | F29: =G28 -> 22.23 | G29: 25.4 | H29: 9 | I29: 25.4
A30: =B29 -> 25.4 | B30: 31.75 | C30: 10 | D30: 31.75 | F30: =G29 -> 25.4 | G30: 31.75 | H30: 10 | I30: 31.75
A31: =B30 -> 31.75 | B31: 44.44 | C31: 11 | D31: 44.44 | F31: =G30 -> 31.75 | G31: 44.44 | H31: 11 | I31: 44.44
A32: =B31 -> 44.44 | B32: 50.8 | C32: 12 | D32: 50.8 | F32: =G31 -> 44.44 | G32: 50.8 | H32: 12 | I32: 50.8
A33: =B32 -> 50.8 | B33: 63.5 | C33: 13 | D33: 63.5 | F33: =G32 -> 50.8 | G33: 63.5 | H33: 13 | I33: 63.5
C34: RESULTADO | D34: RESULTADO | H34: RESULTADO | I34: RESULTADO
C35: =VLOOKUP(#REF!,A21:C33,3) -> #REF! | D35: =VLOOKUP(C35,C21:D33,2) -> #REF! | H35: =VLOOKUP(#REF!,F21:H33,3) -> #REF! | I35: =VLOOKUP(H35,H21:I33,2) -> #REF!

Sheet AÇOS
A1: ÍNDICE | B1: Aço | C1: Fy | D1: Fu | E1: Unidade
A2: 3 | B2: SAE 1020 | C2: 24 | D2: 38.7 | E2: kN/cm²
B3: ASTM A36 | C3: 25 | D3: 40 | E3: kN/cm²
B4: ASTM A588 | C4: 34.5 | D4: 48.5 | E4: kN/cm²
B5: RESULTADO
B6: =INDEX(B2:B4,$A$2) -> ASTM A588 | C6: =INDEX(C2:C4,$A$2) -> 34.5 | D6: =INDEX(D2:D4,$A$2) -> 48.5 | E6: =INDEX(E2:E4,$A$2) -> kN/cm²

Sheet CONCRETOS
A1: ÍNDICE | B1: Concreto | C1: fck | D1: Fu | E1: Unidade
A2: 3 | B2: 20 | C2: 2
B3: 25 | C3: 2.5
B4: 30 | C4: 3
B5: 35 | C5: 3.5
B6: 40 | C6: 4
B7: RESULTADO
B8: =INDEX(B2:B6,$A$2) -> 30 | C8: =INDEX(C2:C6,$A$2) -> 3 | D8: =INDEX(D2:D6,$A$2) -> 0 | E8: =INDEX(E2:E6,$A$2) -> 0
A10: fck = resistência prevista para o concreto aos 28 dias em kN/cm2

Sheet TABELA DE PERFIS W-HP
